Workbook

Sheet Dashboard
B1: KARAN ENTERPRISES
B2: HR Payroll Dashboard • Financial Year 2026–27 (Apr 2026 – Mar 2027)
B4: Select Employee: | C4: Md. Tohid Ansari | L4: YTD | M4: Year to Date | N4: beginning of the current year up to the present date.
B5: Type: | C5: =IFERROR(VLOOKUP($C$4,Lists!$A:$D,2,0),"") | D5: Designation: | E5: =IFERROR(VLOOKUP($C$4,Lists!$A:$D,3,0),"") | F5: Site: | G5: =IFERROR(VLOOKUP($C$4,Lists!$A:$D,4,0),"")
B7: Net Payable (YTD) | D7: Advance Paid (YTD) | F7: Leaves Allotted (YTD) | H7: Total Paid (YTD) | J7: Total Due (YTD)
B8: =SUMIFS('Master Data'!$Q:$Q,'Master Data'!$B:$B,$C$4) -> -6325.8958 | D8: =SUMIFS('Master Data'!$O:$O,'Master Data'!$B:$B,$C$4) -> 26777.516 | F8: =SUMIFS('Master Data'!$J:$J,'Master Data'!$B:$B,$C$4) -> 6 | H8: =SUMIFS('Master Data'!$R:$R,'Master Data'!$B:$B,$C$4) -> 25000 | J8: =SUMIFS('Master Data'!$S:$S,'Master Data'!$B:$B,$C$4) -> -31325.896
B11: Metric / Month | C11: Apr 2026 | D11: May 2026 | E11: Jun 2026 | F11: Jul 2026 | G11: Aug 2026 | H11: Sep 2026 | I11: Oct 2026 | J11: Nov 2026 | K11: Dec 2026 | L11: Jan 2027 | M11: Feb 2027 | N11: Mar 2027 | O11: YTD Total
B12: Working Days | C12: =SUMIFS('Master Data'!$F:$F,'Master Data'!$A:$A,$C$11,'Master Data'!$B:$B,$C$4) -> 30 | D12: =SUMIFS('Master Data'!$F:$F,'Master Data'!$A:$A,$D$11,'Master Data'!$B:$B,$C$4) -> 31 | E12: =SUMIFS('Master Data'!$F:$F,'Master Data'!$A:$A,$E$11,'Master Data'!$B:$B,$C$4) -> 0 | F12: =SUMIFS('Master Data'!$F:$F,'Master Data'!$A:$A,$F$11,'Master Data'!$B:$B,$C$4) -> 0 | G12: =SUMIFS('Master Data'!$F:$F,'Master Data'!$A:$A,$G$11,'Master Data'!$B:$B,$C$4) -> 0 | H12: =SUMIFS('Master Data'!$F:$F,'Master Data'!$A:$A,$H$11,'Master Data'!$B:$B,$C$4) -> 0 | I12: =SUMIFS('Master Data'!$F:$F,'Master Data'!$A:$A,$I$11,'Master Data'!$B:$B,$C$4) -> 0 | J12: =SUMIFS('Master Data'!$F:$F,'Master Data'!$A:$A,$J$11,'Master Data'!$B:$B,$C$4) -> 0 | K12: =SUMIFS('Master Data'!$F:$F,'Master Data'!$A:$A,$K$11,'Master Data'!$B:$B,$C$4) -> 0 | L12: =SUMIFS('Master Data'!$F:$F,'Master Data'!$A:$A,$L$11,'Master Data'!$B:$B,$C$4) -> 0 | M12: =SUMIFS('Master Data'!$F:$F,'Master Data'!$A:$A,$M$11,'Master Data'!$B:$B,$C$4) -> 0 | N12: =SUMIFS('Master Data'!$F:$F,'Master Data'!$A:$A,$N$11,'Master Data'!$B:$B,$C$4) -> 0
B13: Present Days | C13: =SUMIFS('Master Data'!$G:$G,'Master Data'!$A:$A,$C$11,'Master Data'!$B:$B,$C$4) -> 22 | D13: =SUMIFS('Master Data'!$G:$G,'Master Data'!$A:$A,$D$11,'Master Data'!$B:$B,$C$4) -> 24 | E13: =SUMIFS('Master Data'!$G:$G,'Master Data'!$A:$A,$E$11,'Master Data'!$B:$B,$C$4) -> 0 | F13: =SUMIFS('Master Data'!$G:$G,'Master Data'!$A:$A,$F$11,'Master Data'!$B:$B,$C$4) -> 0 | G13: =SUMIFS('Master Data'!$G:$G,'Master Data'!$A:$A,$G$11,'Master Data'!$B:$B,$C$4) -> 0 | H13: =SUMIFS('Master Data'!$G:$G,'Master Data'!$A:$A,$H$11,'Master Data'!$B:$B,$C$4) -> 0 | I13: =SUMIFS('Master Data'!$G:$G,'Master Data'!$A:$A,$I$11,'Master Data'!$B:$B,$C$4) -> 0 | J13: =SUMIFS('Master Data'!$G:$G,'Master Data'!$A:$A,$J$11,'Master Data'!$B:$B,$C$4) -> 0 | K13: =SUMIFS('Master Data'!$G:$G,'Master Data'!$A:$A,$K$11,'Master Data'!$B:$B,$C$4) -> 0 | L13: =SUMIFS('Master Data'!$G:$G,'Master Data'!$A:$A,$L$11,'Master Data'!$B:$B,$C$4) -> 0 | M13: =SUMIFS('Master Data'!$G:$G,'Master Data'!$A:$A,$M$11,'Master Data'!$B:$B,$C$4) -> 0 | N13: =SUMIFS('Master Data'!$G:$G,'Master Data'!$A:$A,$N$11,'Master Data'!$B:$B,$C$4) -> 0
B14: Absent Days | C14: =SUMIFS('Master Data'!$H:$H,'Master Data'!$A:$A,$C$11,'Master Data'!$B:$B,$C$4) -> 8 | D14: =SUMIFS('Master Data'!$H:$H,'Master Data'!$A:$A,$D$11,'Master Data'!$B:$B,$C$4) -> 7 | E14: =SUMIFS('Master Data'!$H:$H,'Master Data'!$A:$A,$E$11,'Master Data'!$B:$B,$C$4) -> 0 | F14: =SUMIFS('Master Data'!$H:$H,'Master Data'!$A:$A,$F$11,'Master Data'!$B:$B,$C$4) -> 0 | G14: =SUMIFS('Master Data'!$H:$H,'Master Data'!$A:$A,$G$11,'Master Data'!$B:$B,$C$4) -> 0 | H14: =SUMIFS('Master Data'!$H:$H,'Master Data'!$A:$A,$H$11,'Master Data'!$B:$B,$C$4) -> 0 | I14: =SUMIFS('Master Data'!$H:$H,'Master Data'!$A:$A,$I$11,'Master Data'!$B:$B,$C$4) -> 0 | J14: =SUMIFS('Master Data'!$H:$H,'Master Data'!$A:$A,$J$11,'Master Data'!$B:$B,$C$4) -> 0 | K14: =SUMIFS('Master Data'!$H:$H,'Master Data'!$A:$A,$K$11,'Master Data'!$B:$B,$C$4) -> 0 | L14: =SUMIFS('Master Data'!$H:$H,'Master Data'!$A:$A,$L$11,'Master Data'!$B:$B,$C$4) -> 0 | M14: =SUMIFS('Master Data'!$H:$H,'Master Data'!$A:$A,$M$11,'Master Data'!$B:$B,$C$4) -> 0 | N14: =SUMIFS('Master Data'!$H:$H,'Master Data'!$A:$A,$N$11,'Master Data'!$B:$B,$C$4) -> 0
B15: Leaves Allotted | C15: =SUMIFS('Master Data'!$J:$J,'Master Data'!$A:$A,$C$11,'Master Data'!$B:$B,$C$4) -> 3 | D15: =SUMIFS('Master Data'!$J:$J,'Master Data'!$A:$A,$D$11,'Master Data'!$B:$B,$C$4) -> 3 | E15: =SUMIFS('Master Data'!$J:$J,'Master Data'!$A:$A,$E$11,'Master Data'!$B:$B,$C$4) -> 0 | F15: =SUMIFS('Master Data'!$J:$J,'Master Data'!$A:$A,$F$11,'Master Data'!$B:$B,$C$4) -> 0 | G15: =SUMIFS('Master Data'!$J:$J,'Master Data'!$A:$A,$G$11,'Master Data'!$B:$B,$C$4) -> 0 | H15: =SUMIFS('Master Data'!$J:$J,'Master Data'!$A:$A,$H$11,'Master Data'!$B:$B,$C$4) -> 0 | I15: =SUMIFS('Master Data'!$J:$J,'Master Data'!$A:$A,$I$11,'Master Data'!$B:$B,$C$4) -> 0 | J15: =SUMIFS('Master Data'!$J:$J,'Master Data'!$A:$A,$J$11,'Master Data'!$B:$B,$C$4) -> 0 | K15: =SUMIFS('Master Data'!$J:$J,'Master Data'!$A:$A,$K$11,'Master Data'!$B:$B,$C$4) -> 0 | L15: =SUMIFS('Master Data'!$J:$J,'Master Data'!$A:$A,$L$11,'Master Data'!$B:$B,$C$4) -> 0 | M15: =SUMIFS('Master Data'!$J:$J,'Master Data'!$A:$A,$M$11,'Master Data'!$B:$B,$C$4) -> 0 | N15: =SUMIFS('Master Data'!$J:$J,'Master Data'!$A:$A,$N$11,'Master Data'!$B:$B,$C$4) -> 0 | O15: =SUM(C15:N15) -> 6
B16: Leaves Availed | C16: =SUMIFS('Master Data'!$K:$K,'Master Data'!$A:$A,$C$11,'Master Data'!$B:$B,$C$4) -> 3 | D16: =SUMIFS('Master Data'!$K:$K,'Master Data'!$A:$A,$D$11,'Master Data'!$B:$B,$C$4) -> 3 | E16: =SUMIFS('Master Data'!$K:$K,'Master Data'!$A:$A,$E$11,'Master Data'!$B:$B,$C$4) -> 0 | F16: =SUMIFS('Master Data'!$K:$K,'Master Data'!$A:$A,$F$11,'Master Data'!$B:$B,$C$4) -> 0 | G16: =SUMIFS('Master Data'!$K:$K,'Master Data'!$A:$A,$G$11,'Master Data'!$B:$B,$C$4) -> 0 | H16: =SUMIFS('Master Data'!$K:$K,'Master Data'!$A:$A,$H$11,'Master Data'!$B:$B,$C$4) -> 0 | I16: =SUMIFS('Master Data'!$K:$K,'Master Data'!$A:$A,$I$11,'Master Data'!$B:$B,$C$4) -> 0 | J16: =SUMIFS('Master Data'!$K:$K,'Master Data'!$A:$A,$J$11,'Master Data'!$B:$B,$C$4) -> 0 | K16: =SUMIFS('Master Data'!$K:$K,'Master Data'!$A:$A,$K$11,'Master Data'!$B:$B,$C$4) -> 0 | L16: =SUMIFS('Master Data'!$K:$K,'Master Data'!$A:$A,$L$11,'Master Data'!$B:$B,$C$4) -> 0 | M16: =SUMIFS('Master Data'!$K:$K,'Master Data'!$A:$A,$M$11,'Master Data'!$B:$B,$C$4) -> 0 | N16: =SUMIFS('Master Data'!$K:$K,'Master Data'!$A:$A,$N$11,'Master Data'!$B:$B,$C$4) -> 0 | O16: =SUM(C16:N16) -> 6
B17: Leave Balance (Closing) | C17: =SUMIFS('Master Data'!$L:$L,'Master Data'!$A:$A,$C$11,'Master Data'!$B:$B,$C$4) -> 0 | D17: =SUMIFS('Master Data'!$L:$L,'Master Data'!$A:$A,$D$11,'Master Data'!$B:$B,$C$4) -> 0 | E17: =SUMIFS('Master Data'!$L:$L,'Master Data'!$A:$A,$E$11,'Master Data'!$B:$B,$C$4) -> 0 | F17: =SUMIFS('Master Data'!$L:$L,'Master Data'!$A:$A,$F$11,'Master Data'!$B:$B,$C$4) -> 0 | G17: =SUMIFS('Master Data'!$L:$L,'Master Data'!$A:$A,$G$11,'Master Data'!$B:$B,$C$4) -> 0 | H17: =SUMIFS('Master Data'!$L:$L,'Master Data'!$A:$A,$H$11,'Master Data'!$B:$B,$C$4) -> 0 | I17: =SUMIFS('Master Data'!$L:$L,'Master Data'!$A:$A,$I$11,'Master Data'!$B:$B,$C$4) -> 0 | J17: =SUMIFS('Master Data'!$L:$L,'Master Data'!$A:$A,$J$11,'Master Data'!$B:$B,$C$4) -> 0 | K17: =SUMIFS('Master Data'!$L:$L,'Master Data'!$A:$A,$K$11,'Master Data'!$B:$B,$C$4) -> 0 | L17: =SUMIFS('Master Data'!$L:$L,'Master Data'!$A:$A,$L$11,'Master Data'!$B:$B,$C$4) -> 0 | M17: =SUMIFS('Master Data'!$L:$L,'Master Data'!$A:$A,$M$11,'Master Data'!$B:$B,$C$4) -> 0 | N17: =SUMIFS('Master Data'!$L:$L,'Master Data'!$A:$A,$N$11,'Master Data'!$B:$B,$C$4) -> 0 | O17: =IFERROR(LOOKUP(2,1/(($A$1:$A$1="")+('Master Data'!$B:$B=$C$4)*('Master Data'!$L:$L<>"")),'Master Data'!$L:$L),"") -> 0
B18: Salary (Gross) | C18: =SUMIFS('Master Data'!$M:$M,'Master Data'!$A:$A,$C$11,'Master Data'!$B:$B,$C$4) -> 12000 | D18: =SUMIFS('Master Data'!$M:$M,'Master Data'!$A:$A,$D$11,'Master Data'!$B:$B,$C$4) -> 12000 | E18: =SUMIFS('Master Data'!$M:$M,'Master Data'!$A:$A,$E$11,'Master Data'!$B:$B,$C$4) -> 0 | F18: =SUMIFS('Master Data'!$M:$M,'Master Data'!$A:$A,$F$11,'Master Data'!$B:$B,$C$4) -> 0 | G18: =SUMIFS('Master Data'!$M:$M,'Master Data'!$A:$A,$G$11,'Master Data'!$B:$B,$C$4) -> 0 | H18: =SUMIFS('Master Data'!$M:$M,'Master Data'!$A:$A,$H$11,'Master Data'!$B:$B,$C$4) -> 0 | I18: =SUMIFS('Master Data'!$M:$M,'Master Data'!$A:$A,$I$11,'Master Data'!$B:$B,$C$4) -> 0 | J18: =SUMIFS('Master Data'!$M:$M,'Master Data'!$A:$A,$J$11,'Master Data'!$B:$B,$C$4) -> 0 | K18: =SUMIFS('Master Data'!$M:$M,'Master Data'!$A:$A,$K$11,'Master Data'!$B:$B,$C$4) -> 0 | L18: =SUMIFS('Master Data'!$M:$M,'Master Data'!$A:$A,$L$11,'Master Data'!$B:$B,$C$4) -> 0 | M18: =SUMIFS('Master Data'!$M:$M,'Master Data'!$A:$A,$M$11,'Master Data'!$B:$B,$C$4) -> 0 | N18: =SUMIFS('Master Data'!$M:$M,'Master Data'!$A:$A,$N$11,'Master Data'!$B:$B,$C$4) -> 0 | O18: =SUM(C18:N18) -> 24000
B19: Salary Earned | C19: =SUMIFS('Master Data'!$N:$N,'Master Data'!$A:$A,$C$11,'Master Data'!$B:$B,$C$4) -> 10000 | D19: =SUMIFS('Master Data'!$N:$N,'Master Data'!$A:$A,$D$11,'Master Data'!$B:$B,$C$4) -> 10451.61 | E19: =SUMIFS('Master Data'!$N:$N,'Master Data'!$A:$A,$E$11,'Master Data'!$B:$B,$C$4) -> 0 | F19: =SUMIFS('Master Data'!$N:$N,'Master Data'!$A:$A,$F$11,'Master Data'!$B:$B,$C$4) -> 0 | G19: =SUMIFS('Master Data'!$N:$N,'Master Data'!$A:$A,$G$11,'Master Data'!$B:$B,$C$4) -> 0 | H19: =SUMIFS('Master Data'!$N:$N,'Master Data'!$A:$A,$H$11,'Master Data'!$B:$B,$C$4) -> 0 | I19: =SUMIFS('Master Data'!$N:$N,'Master Data'!$A:$A,$I$11,'Master Data'!$B:$B,$C$4) -> 0 | J19: =SUMIFS('Master Data'!$N:$N,'Master Data'!$A:$A,$J$11,'Master Data'!$B:$B,$C$4) -> 0 | K19: =SUMIFS('Master Data'!$N:$N,'Master Data'!$A:$A,$K$11,'Master Data'!$B:$B,$C$4) -> 0 | L19: =SUMIFS('Master Data'!$N:$N,'Master Data'!$A:$A,$L$11,'Master Data'!$B:$B,$C$4) -> 0 | M19: =SUMIFS('Master Data'!$N:$N,'Master Data'!$A:$A,$M$11,'Master Data'!$B:$B,$C$4) -> 0 | N19: =SUMIFS('Master Data'!$N:$N,'Master Data'!$A:$A,$N$11,'Master Data'!$B:$B,$C$4) -> 0 | O19: =SUM(C19:N19) -> 20451.61
B20: Advance Deducted | C20: =SUMIFS('Master Data'!$O:$O,'Master Data'!$A:$A,$C$11,'Master Data'!$B:$B,$C$4) -> 5888.7558 | D20: =SUMIFS('Master Data'!$O:$O,'Master Data'!$A:$A,$D$11,'Master Data'!$B:$B,$C$4) -> 20888.76 | E20: =SUMIFS('Master Data'!$O:$O,'Master Data'!$A:$A,$E$11,'Master Data'!$B:$B,$C$4) -> 0 | F20: =SUMIFS('Master Data'!$O:$O,'Master Data'!$A:$A,$F$11,'Master Data'!$B:$B,$C$4) -> 0 | G20: =SUMIFS('Master Data'!$O:$O,'Master Data'!$A:$A,$G$11,'Master Data'!$B:$B,$C$4) -> 0 | H20: =SUMIFS('Master Data'!$O:$O,'Master Data'!$A:$A,$H$11,'Master Data'!$B:$B,$C$4) -> 0 | I20: =SUMIFS('Master Data'!$O:$O,'Master Data'!$A:$A,$I$11,'Master Data'!$B:$B,$C$4) -> 0 | J20: =SUMIFS('Master Data'!$O:$O,'Master Data'!$A:$A,$J$11,'Master Data'!$B:$B,$C$4) -> 0 | K20: =SUMIFS('Master Data'!$O:$O,'Master Data'!$A:$A,$K$11,'Master Data'!$B:$B,$C$4) -> 0 | L20: =SUMIFS('Master Data'!$O:$O,'Master Data'!$A:$A,$L$11,'Master Data'!$B:$B,$C$4) -> 0 | M20: =SUMIFS('Master Data'!$O:$O,'Master Data'!$A:$A,$M$11,'Master Data'!$B:$B,$C$4) -> 0 | N20: =SUMIFS('Master Data'!$O:$O,'Master Data'!$A:$A,$N$11,'Master Data'!$B:$B,$C$4) -> 0 | O20: =SUM(C20:N20) -> 26777.516
B21: Bonus / Inclusion | C21: =SUMIFS('Master Data'!$P:$P,'Master Data'!$A:$A,$C$11,'Master Data'!$B:$B,$C$4) -> 0 | D21: =SUMIFS('Master Data'!$P:$P,'Master Data'!$A:$A,$D$11,'Master Data'!$B:$B,$C$4) -> 0 | E21: =SUMIFS('Master Data'!$P:$P,'Master Data'!$A:$A,$E$11,'Master Data'!$B:$B,$C$4) -> 0 | F21: =SUMIFS('Master Data'!$P:$P,'Master Data'!$A:$A,$F$11,'Master Data'!$B:$B,$C$4) -> 0 | G21: =SUMIFS('Master Data'!$P:$P,'Master Data'!$A:$A,$G$11,'Master Data'!$B:$B,$C$4) -> 0 | H21: =SUMIFS('Master Data'!$P:$P,'Master Data'!$A:$A,$H$11,'Master Data'!$B:$B,$C$4) -> 0 | I21: =SUMIFS('Master Data'!$P:$P,'Master Data'!$A:$A,$I$11,'Master Data'!$B:$B,$C$4) -> 0 | J21: =SUMIFS('Master Data'!$P:$P,'Master Data'!$A:$A,$J$11,'Master Data'!$B:$B,$C$4) -> 0 | K21: =SUMIFS('Master Data'!$P:$P,'Master Data'!$A:$A,$K$11,'Master Data'!$B:$B,$C$4) -> 0 | L21: =SUMIFS('Master Data'!$P:$P,'Master Data'!$A:$A,$L$11,'Master Data'!$B:$B,$C$4) -> 0 | M21: =SUMIFS('Master Data'!$P:$P,'Master Data'!$A:$A,$M$11,'Master Data'!$B:$B,$C$4) -> 0 | N21: =SUMIFS('Master Data'!$P:$P,'Master Data'!$A:$A,$N$11,'Master Data'!$B:$B,$C$4) -> 0 | O21: =SUM(C21:N21) -> 0
B22: Net Payable | C22: =SUMIFS('Master Data'!$Q:$Q,'Master Data'!$A:$A,$C$11,'Master Data'!$B:$B,$C$4) -> 4111.2442 | D22: =SUMIFS('Master Data'!$Q:$Q,'Master Data'!$A:$A,$D$11,'Master Data'!$B:$B,$C$4) -> -10437.14 | E22: =SUMIFS('Master Data'!$Q:$Q,'Master Data'!$A:$A,$E$11,'Master Data'!$B:$B,$C$4) -> 0 | F22: =SUMIFS('Master Data'!$Q:$Q,'Master Data'!$A:$A,$F$11,'Master Data'!$B:$B,$C$4) -> 0 | G22: =SUMIFS('Master Data'!$Q:$Q,'Master Data'!$A:$A,$G$11,'Master Data'!$B:$B,$C$4) -> 0 | H22: =SUMIFS('Master Data'!$Q:$Q,'Master Data'!$A:$A,$H$11,'Master Data'!$B:$B,$C$4) -> 0 | I22: =SUMIFS('Master Data'!$Q:$Q,'Master Data'!$A:$A,$I$11,'Master Data'!$B:$B,$C$4) -> 0 | J22: =SUMIFS('Master Data'!$Q:$Q,'Master Data'!$A:$A,$J$11,'Master Data'!$B:$B,$C$4) -> 0 | K22: =SUMIFS('Master Data'!$Q:$Q,'Master Data'!$A:$A,$K$11,'Master Data'!$B:$B,$C$4) -> 0 | L22: =SUMIFS('Master Data'!$Q:$Q,'Master Data'!$A:$A,$L$11,'Master Data'!$B:$B,$C$4) -> 0 | M22: =SUMIFS('Master Data'!$Q:$Q,'Master Data'!$A:$A,$M$11,'Master Data'!$B:$B,$C$4) -> 0 | N22: =SUMIFS('Master Data'!$Q:$Q,'Master Data'!$A:$A,$N$11,'Master Data'!$B:$B,$C$4) -> 0 | O22: =SUM(C22:N22) -> -6325.8958
B23: Paid | C23: =SUMIFS('Master Data'!$R:$R,'Master Data'!$A:$A,$C$11,'Master Data'!$B:$B,$C$4) -> 25000 | D23: =SUMIFS('Master Data'!$R:$R,'Master Data'!$A:$A,$D$11,'Master Data'!$B:$B,$C$4) -> 0 | E23: =SUMIFS('Master Data'!$R:$R,'Master Data'!$A:$A,$E$11,'Master Data'!$B:$B,$C$4) -> 0 | F23: =SUMIFS('Master Data'!$R:$R,'Master Data'!$A:$A,$F$11,'Master Data'!$B:$B,$C$4) -> 0 | G23: =SUMIFS('Master Data'!$R:$R,'Master Data'!$A:$A,$G$11,'Master Data'!$B:$B,$C$4) -> 0 | H23: =SUMIFS('Master Data'!$R:$R,'Master Data'!$A:$A,$H$11,'Master Data'!$B:$B,$C$4) -> 0 | I23: =SUMIFS('Master Data'!$R:$R,'Master Data'!$A:$A,$I$11,'Master Data'!$B:$B,$C$4) -> 0 | J23: =SUMIFS('Master Data'!$R:$R,'Master Data'!$A:$A,$J$11,'Master Data'!$B:$B,$C$4) -> 0 | K23: =SUMIFS('Master Data'!$R:$R,'Master Data'!$A:$A,$K$11,'Master Data'!$B:$B,$C$4) -> 0 | L23: =SUMIFS('Master Data'!$R:$R,'Master Data'!$A:$A,$L$11,'Master Data'!$B:$B,$C$4) -> 0 | M23: =SUMIFS('Master Data'!$R:$R,'Master Data'!$A:$A,$M$11,'Master Data'!$B:$B,$C$4) -> 0 | N23: =SUMIFS('Master Data'!$R:$R,'Master Data'!$A:$A,$N$11,'Master Data'!$B:$B,$C$4) -> 0 | O23: =SUM(C23:N23) -> 25000
B24: Due to be paid | C24: =SUMIFS('Master Data'!$S:$S,'Master Data'!$A:$A,$C$11,'Master Data'!$B:$B,$C$4) -> -20888.756 | D24: =SUMIFS('Master Data'!$S:$S,'Master Data'!$A:$A,$D$11,'Master Data'!$B:$B,$C$4) -> -10437.14 | E24: =SUMIFS('Master Data'!$S:$S,'Master Data'!$A:$A,$E$11,'Master Data'!$B:$B,$C$4) -> 0 | F24: =SUMIFS('Master Data'!$S:$S,'Master Data'!$A:$A,$F$11,'Master Data'!$B:$B,$C$4) -> 0 | G24: =SUMIFS('Master Data'!$S:$S,'Master Data'!$A:$A,$G$11,'Master Data'!$B:$B,$C$4) -> 0 | H24: =SUMIFS('Master Data'!$S:$S,'Master Data'!$A:$A,$H$11,'Master Data'!$B:$B,$C$4) -> 0 | I24: =SUMIFS('Master Data'!$S:$S,'Master Data'!$A:$A,$I$11,'Master Data'!$B:$B,$C$4) -> 0 | J24: =SUMIFS('Master Data'!$S:$S,'Master Data'!$A:$A,$J$11,'Master Data'!$B:$B,$C$4) -> 0 | K24: =SUMIFS('Master Data'!$S:$S,'Master Data'!$A:$A,$K$11,'Master Data'!$B:$B,$C$4) -> 0 | L24: =SUMIFS('Master Data'!$S:$S,'Master Data'!$A:$A,$L$11,'Master Data'!$B:$B,$C$4) -> 0 | M24: =SUMIFS('Master Data'!$S:$S,'Master Data'!$A:$A,$M$11,'Master Data'!$B:$B,$C$4) -> 0 | N24: =SUMIFS('Master Data'!$S:$S,'Master Data'!$A:$A,$N$11,'Master Data'!$B:$B,$C$4) -> 0 | O24: =SUM(C24:N24) -> -31325.896

Sheet Company Summary
B1: KARAN ENTERPRISES
B2: All employees | Financial Year 2026–27
B4: Metric / Month | C4: Apr 2026 | D4: May 2026 | E4: Jun 2026 | F4: Jul 2026 | G4: Aug 2026 | H4: Sep 2026 | I4: Oct 2026 | J4: Nov 2026 | K4: Dec 2026 | L4: Jan 2027 | M4: Feb 2027 | N4: Mar 2027 | O4: YTD Total
B5: Headcount (with data) | C5: =COUNTIFS('Master Data'!$A:$A,$C$4) -> 184 | D5: =COUNTIFS('Master Data'!$A:$A,$D$4) -> 186 | E5: =COUNTIFS('Master Data'!$A:$A,$E$4) -> 0 | F5: =COUNTIFS('Master Data'!$A:$A,$F$4) -> 0 | G5: =COUNTIFS('Master Data'!$A:$A,$G$4) -> 0 | H5: =COUNTIFS('Master Data'!$A:$A,$H$4) -> 0 | I5: =COUNTIFS('Master Data'!$A:$A,$I$4) -> 0 | J5: =COUNTIFS('Master Data'!$A:$A,$J$4) -> 0 | K5: =COUNTIFS('Master Data'!$A:$A,$K$4) -> 0 | L5: =COUNTIFS('Master Data'!$A:$A,$L$4) -> 0 | M5: =COUNTIFS('Master Data'!$A:$A,$M$4) -> 0 | N5: =COUNTIFS('Master Data'!$A:$A,$N$4) -> 0 | O5: =MAX(C5:N5) -> 186
B6: Total Present Days | C6: =SUMIFS('Master Data'!$G:$G,'Master Data'!$A:$A,$C$4) -> 2597 | D6: =SUMIFS('Master Data'!$G:$G,'Master Data'!$A:$A,$D$4) -> 2607.5 | E6: =SUMIFS('Master Data'!$G:$G,'Master Data'!$A:$A,$E$4) -> 0 | F6: =SUMIFS('Master Data'!$G:$G,'Master Data'!$A:$A,$F$4) -> 0 | G6: =SUMIFS('Master Data'!$G:$G,'Master Data'!$A:$A,$G$4) -> 0 | H6: =SUMIFS('Master Data'!$G:$G,'Master Data'!$A:$A,$H$4) -> 0 | I6: =SUMIFS('Master Data'!$G:$G,'Master Data'!$A:$A,$I$4) -> 0 | J6: =SUMIFS('Master Data'!$G:$G,'Master Data'!$A:$A,$J$4) -> 0 | K6: =SUMIFS('Master Data'!$G:$G,'Master Data'!$A:$A,$K$4) -> 0 | L6: =SUMIFS('Master Data'!$G:$G,'Master Data'!$A:$A,$L$4) -> 0 | M6: =SUMIFS('Master Data'!$G:$G,'Master Data'!$A:$A,$M$4) -> 0 | N6: =SUMIFS('Master Data'!$G:$G,'Master Data'!$A:$A,$N$4) -> 0 | O6: =SUM(C6:N6) -> 5204.5
B7: Total Absent Days | C7: =SUMIFS('Master Data'!$H:$H,'Master Data'!$A:$A,$C$4) -> 2923 | D7: =SUMIFS('Master Data'!$H:$H,'Master Data'!$A:$A,$D$4) -> 3158.5 | E7: =SUMIFS('Master Data'!$H:$H,'Master Data'!$A:$A,$E$4) -> 0 | F7: =SUMIFS('Master Data'!$H:$H,'Master Data'!$A:$A,$F$4) -> 0 | G7: =SUMIFS('Master Data'!$H:$H,'Master Data'!$A:$A,$G$4) -> 0 | H7: =SUMIFS('Master Data'!$H:$H,'Master Data'!$A:$A,$H$4) -> 0 | I7: =SUMIFS('Master Data'!$H:$H,'Master Data'!$A:$A,$I$4) -> 0 | J7: =SUMIFS('Master Data'!$H:$H,'Master Data'!$A:$A,$J$4) -> 0 | K7: =SUMIFS('Master Data'!$H:$H,'Master Data'!$A:$A,$K$4) -> 0 | L7: =SUMIFS('Master Data'!$H:$H,'Master Data'!$A:$A,$L$4) -> 0 | M7: =SUMIFS('Master Data'!$H:$H,'Master Data'!$A:$A,$M$4) -> 0 | N7: =SUMIFS('Master Data'!$H:$H,'Master Data'!$A:$A,$N$4) -> 0 | O7: =SUM(C7:N7) -> 6081.5
B8: Total Leaves Allotted | C8: =SUMIFS('Master Data'!$J:$J,'Master Data'!$A:$A,$C$4) -> 367 | D8: =SUMIFS('Master Data'!$J:$J,'Master Data'!$A:$A,$D$4) -> 590 | E8: =SUMIFS('Master Data'!$J:$J,'Master Data'!$A:$A,$E$4) -> 0 | F8: =SUMIFS('Master Data'!$J:$J,'Master Data'!$A:$A,$F$4) -> 0 | G8: =SUMIFS('Master Data'!$J:$J,'Master Data'!$A:$A,$G$4) -> 0 | H8: =SUMIFS('Master Data'!$J:$J,'Master Data'!$A:$A,$H$4) -> 0 | I8: =SUMIFS('Master Data'!$J:$J,'Master Data'!$A:$A,$I$4) -> 0 | J8: =SUMIFS('Master Data'!$J:$J,'Master Data'!$A:$A,$J$4) -> 0 | K8: =SUMIFS('Master Data'!$J:$J,'Master Data'!$A:$A,$K$4) -> 0 | L8: =SUMIFS('Master Data'!$J:$J,'Master Data'!$A:$A,$L$4) -> 0 | M8: =SUMIFS('Master Data'!$J:$J,'Master Data'!$A:$A,$M$4) -> 0 | N8: =SUMIFS('Master Data'!$J:$J,'Master Data'!$A:$A,$N$4) -> 0 | O8: =SUM(C8:N8) -> 957
B9: Total Leaves Availed | C9: =SUMIFS('Master Data'!$K:$K,'Master Data'!$A:$A,$C$4) -> 185 | D9: =SUMIFS('Master Data'!$K:$K,'Master Data'!$A:$A,$D$4) -> 283 | E9: =SUMIFS('Master Data'!$K:$K,'Master Data'!$A:$A,$E$4) -> 0 | F9: =SUMIFS('Master Data'!$K:$K,'Master Data'!$A:$A,$F$4) -> 0 | G9: =SUMIFS('Master Data'!$K:$K,'Master Data'!$A:$A,$G$4) -> 0 | H9: =SUMIFS('Master Data'!$K:$K,'Master Data'!$A:$A,$H$4) -> 0 | I9: =SUMIFS('Master Data'!$K:$K,'Master Data'!$A:$A,$I$4) -> 0 | J9: =SUMIFS('Master Data'!$K:$K,'Master Data'!$A:$A,$J$4) -> 0 | K9: =SUMIFS('Master Data'!$K:$K,'Master Data'!$A:$A,$K$4) -> 0 | L9: =SUMIFS('Master Data'!$K:$K,'Master Data'!$A:$A,$L$4) -> 0 | M9: =SUMIFS('Master Data'!$K:$K,'Master Data'!$A:$A,$M$4) -> 0 | N9: =SUMIFS('Master Data'!$K:$K,'Master Data'!$A:$A,$N$4) -> 0 | O9: =SUM(C9:N9) -> 468
B10: Gross Salary | C10: =SUMIFS('Master Data'!$M:$M,'Master Data'!$A:$A,$C$4) -> 2350200 | D10: =SUMIFS('Master Data'!$M:$M,'Master Data'!$A:$A,$D$4) -> 2373200 | E10: =SUMIFS('Master Data'!$M:$M,'Master Data'!$A:$A,$E$4) -> 0 | F10: =SUMIFS('Master Data'!$M:$M,'Master Data'!$A:$A,$F$4) -> 0 | G10: =SUMIFS('Master Data'!$M:$M,'Master Data'!$A:$A,$G$4) -> 0 | H10: =SUMIFS('Master Data'!$M:$M,'Master Data'!$A:$A,$H$4) -> 0 | I10: =SUMIFS('Master Data'!$M:$M,'Master Data'!$A:$A,$I$4) -> 0 | J10: =SUMIFS('Master Data'!$M:$M,'Master Data'!$A:$A,$J$4) -> 0 | K10: =SUMIFS('Master Data'!$M:$M,'Master Data'!$A:$A,$K$4) -> 0 | L10: =SUMIFS('Master Data'!$M:$M,'Master Data'!$A:$A,$L$4) -> 0 | M10: =SUMIFS('Master Data'!$M:$M,'Master Data'!$A:$A,$M$4) -> 0 | N10: =SUMIFS('Master Data'!$M:$M,'Master Data'!$A:$A,$N$4) -> 0 | O10: =SUM(C10:N10) -> 4723400
B11: Salary Earned | C11: =SUMIFS('Master Data'!$N:$N,'Master Data'!$A:$A,$C$4) -> 1313483.3 | D11: =SUMIFS('Master Data'!$N:$N,'Master Data'!$A:$A,$D$4) -> 1275687.1 | E11: =SUMIFS('Master Data'!$N:$N,'Master Data'!$A:$A,$E$4) -> 0 | F11: =SUMIFS('Master Data'!$N:$N,'Master Data'!$A:$A,$F$4) -> 0 | G11: =SUMIFS('Master Data'!$N:$N,'Master Data'!$A:$A,$G$4) -> 0 | H11: =SUMIFS('Master Data'!$N:$N,'Master Data'!$A:$A,$H$4) -> 0 | I11: =SUMIFS('Master Data'!$N:$N,'Master Data'!$A:$A,$I$4) -> 0 | J11: =SUMIFS('Master Data'!$N:$N,'Master Data'!$A:$A,$J$4) -> 0 | K11: =SUMIFS('Master Data'!$N:$N,'Master Data'!$A:$A,$K$4) -> 0 | L11: =SUMIFS('Master Data'!$N:$N,'Master Data'!$A:$A,$L$4) -> 0 | M11: =SUMIFS('Master Data'!$N:$N,'Master Data'!$A:$A,$M$4) -> 0 | N11: =SUMIFS('Master Data'!$N:$N,'Master Data'!$A:$A,$N$4) -> 0 | O11: =SUM(C11:N11) -> 2589170.4
B12: Advance Deducted | C12: =SUMIFS('Master Data'!$O:$O,'Master Data'!$A:$A,$C$4) -> 228743.56 | D12: =SUMIFS('Master Data'!$O:$O,'Master Data'!$A:$A,$D$4) -> 204182.18 | E12: =SUMIFS('Master Data'!$O:$O,'Master Data'!$A:$A,$E$4) -> 0 | F12: =SUMIFS('Master Data'!$O:$O,'Master Data'!$A:$A,$F$4) -> 0 | G12: =SUMIFS('Master Data'!$O:$O,'Master Data'!$A:$A,$G$4) -> 0 | H12: =SUMIFS('Master Data'!$O:$O,'Master Data'!$A:$A,$H$4) -> 0 | I12: =SUMIFS('Master Data'!$O:$O,'Master Data'!$A:$A,$I$4) -> 0 | J12: =SUMIFS('Master Data'!$O:$O,'Master Data'!$A:$A,$J$4) -> 0 | K12: =SUMIFS('Master Data'!$O:$O,'Master Data'!$A:$A,$K$4) -> 0 | L12: =SUMIFS('Master Data'!$O:$O,'Master Data'!$A:$A,$L$4) -> 0 | M12: =SUMIFS('Master Data'!$O:$O,'Master Data'!$A:$A,$M$4) -> 0 | N12: =SUMIFS('Master Data'!$O:$O,'Master Data'!$A:$A,$N$4) -> 0 | O12: =SUM(C12:N12) -> 432925.74
B13: Bonus / Inclusion | C13: =SUMIFS('Master Data'!$P:$P,'Master Data'!$A:$A,$C$4) -> 908126.88 | D13: =SUMIFS('Master Data'!$P:$P,'Master Data'!$A:$A,$D$4) -> 0 | E13: =SUMIFS('Master Data'!$P:$P,'Master Data'!$A:$A,$E$4) -> 0 | F13: =SUMIFS('Master Data'!$P:$P,'Master Data'!$A:$A,$F$4) -> 0 | G13: =SUMIFS('Master Data'!$P:$P,'Master Data'!$A:$A,$G$4) -> 0 | H13: =SUMIFS('Master Data'!$P:$P,'Master Data'!$A:$A,$H$4) -> 0 | I13: =SUMIFS('Master Data'!$P:$P,'Master Data'!$A:$A,$I$4) -> 0 | J13: =SUMIFS('Master Data'!$P:$P,'Master Data'!$A:$A,$J$4) -> 0 | K13: =SUMIFS('Master Data'!$P:$P,'Master Data'!$A:$A,$K$4) -> 0 | L13: =SUMIFS('Master Data'!$P:$P,'Master Data'!$A:$A,$L$4) -> 0 | M13: =SUMIFS('Master Data'!$P:$P,'Master Data'!$A:$A,$M$4) -> 0 | N13: =SUMIFS('Master Data'!$P:$P,'Master Data'!$A:$A,$N$4) -> 0 | O13: =SUM(C13:N13) -> 908126.88
B14: Net Payable | C14: =SUMIFS('Master Data'!$Q:$Q,'Master Data'!$A:$A,$C$4) -> 1992866.6 | D14: =SUMIFS('Master Data'!$Q:$Q,'Master Data'!$A:$A,$D$4) -> 1233815.7 | E14: =SUMIFS('Master Data'!$Q:$Q,'Master Data'!$A:$A,$E$4) -> 0 | F14: =SUMIFS('Master Data'!$Q:$Q,'Master Data'!$A:$A,$F$4) -> 0 | G14: =SUMIFS('Master Data'!$Q:$Q,'Master Data'!$A:$A,$G$4) -> 0 | H14: =SUMIFS('Master Data'!$Q:$Q,'Master Data'!$A:$A,$H$4) -> 0 | I14: =SUMIFS('Master Data'!$Q:$Q,'Master Data'!$A:$A,$I$4) -> 0 | J14: =SUMIFS('Master Data'!$Q:$Q,'Master Data'!$A:$A,$J$4) -> 0 | K14: =SUMIFS('Master Data'!$Q:$Q,'Master Data'!$A:$A,$K$4) -> 0 | L14: =SUMIFS('Master Data'!$Q:$Q,'Master Data'!$A:$A,$L$4) -> 0 | M14: =SUMIFS('Master Data'!$Q:$Q,'Master Data'!$A:$A,$M$4) -> 0 | N14: =SUMIFS('Master Data'!$Q:$Q,'Master Data'!$A:$A,$N$4) -> 0 | O14: =SUM(C14:N14) -> 3226682.4
B15: Total Paid | C15: =SUMIFS('Master Data'!$R:$R,'Master Data'!$A:$A,$C$4) -> 2034738 | D15: =SUMIFS('Master Data'!$R:$R,'Master Data'!$A:$A,$D$4) -> 3300 | E15: =SUMIFS('Master Data'!$R:$R,'Master Data'!$A:$A,$E$4) -> 0 | F15: =SUMIFS('Master Data'!$R:$R,'Master Data'!$A:$A,$F$4) -> 0 | G15: =SUMIFS('Master Data'!$R:$R,'Master Data'!$A:$A,$G$4) -> 0 | H15: =SUMIFS('Master Data'!$R:$R,'Master Data'!$A:$A,$H$4) -> 0 | I15: =SUMIFS('Master Data'!$R:$R,'Master Data'!$A:$A,$I$4) -> 0 | J15: =SUMIFS('Master Data'!$R:$R,'Master Data'!$A:$A,$J$4) -> 0 | K15: =SUMIFS('Master Data'!$R:$R,'Master Data'!$A:$A,$K$4) -> 0 | L15: =SUMIFS('Master Data'!$R:$R,'Master Data'!$A:$A,$L$4) -> 0 | M15: =SUMIFS('Master Data'!$R:$R,'Master Data'!$A:$A,$M$4) -> 0 | N15: =SUMIFS('Master Data'!$R:$R,'Master Data'!$A:$A,$N$4) -> 0 | O15: =SUM(C15:N15) -> 2038038
B16: Total Due | C16: =SUMIFS('Master Data'!$S:$S,'Master Data'!$A:$A,$C$4) -> -41871.352 | D16: =SUMIFS('Master Data'!$S:$S,'Master Data'!$A:$A,$D$4) -> 1230515.7 | E16: =SUMIFS('Master Data'!$S:$S,'Master Data'!$A:$A,$E$4) -> 0 | F16: =SUMIFS('Master Data'!$S:$S,'Master Data'!$A:$A,$F$4) -> 0 | G16: =SUMIFS('Master Data'!$S:$S,'Master Data'!$A:$A,$G$4) -> 0 | H16: =SUMIFS('Master Data'!$S:$S,'Master Data'!$A:$A,$H$4) -> 0 | I16: =SUMIFS('Master Data'!$S:$S,'Master Data'!$A:$A,$I$4) -> 0 | J16: =SUMIFS('Master Data'!$S:$S,'Master Data'!$A:$A,$J$4) -> 0 | K16: =SUMIFS('Master Data'!$S:$S,'Master Data'!$A:$A,$K$4) -> 0 | L16: =SUMIFS('Master Data'!$S:$S,'Master Data'!$A:$A,$L$4) -> 0 | M16: =SUMIFS('Master Data'!$S:$S,'Master Data'!$A:$A,$M$4) -> 0 | N16: =SUMIFS('Master Data'!$S:$S,'Master Data'!$A:$A,$N$4) -> 0 | O16: =SUM(C16:N16) -> 1188644.4

Sheet Master Data
A1: Month | B1: Employee | C1: Type | D1: Designation | E1: Site | F1: Working Days | G1: Present Days | H1: Absent Days | I1: Opening Leave Bal | J1: Leaves Allotted | K1: Leaves Availed | L1: Closing Leave Bal | M1: Salary (Gross) | N1: Salary Earned | O1: Advance Deducted | P1: Bonus / Inclusion | Q1: Net Payable | R1: Paid | S1: Due
A2: Apr 2026 | B2: Ajit Singh | C2: New | D2: supervisor | E2: Karo | F2: 30 | G2: 27 | H2: 3 | I2: =VLOOKUP(B2,'[1]Wages Sheet'!$B$8:$J$192,9,FALSE) -> -2.5 | J2: =SUM(VLOOKUP(B2,'[1]Wages Sheet'!$B$8:$K$192,10,FALSE)+(VLOOKUP(B2,'[1]Wages Sheet'!$B$8:$L$192,11,FALSE))) -> 4 | K2: =VLOOKUP(B2,'[1]Wages Sheet'!$B$8:$O$192,14,FALSE) -> 3 | L2: =VLOOKUP(B2,'[1]Wages Sheet'!$B$8:$Q$192,16,FALSE) -> 1 | M2: =VLOOKUP(B2,'[1]Wages Sheet'!$B$8:$T$193,19,FALSE) -> 9000 | N2: =VLOOKUP(B2,'[1]Wages Sheet'!$B$8:$U$192,20,FALSE) -> 9000 | O2: =VLOOKUP(B2,'[1]Wages Sheet'!$B$8:$W$192,22,FALSE) -> 0 | P2: =VLOOKUP(B2,'[1]Wages Sheet'!$B$8:$Z$192,25,FALSE) -> 2999.0323 | Q2: =VLOOKUP(B2,'[1]Wages Sheet'!$B$8:$AD$192,28,FALSE) -> 11999.032 | R2: =VLOOKUP(B2,'[1]Wages Sheet'!$B$8:$AD$192,29,FALSE) -> 12000 | S2: =VLOOKUP(B2,'[1]Wages Sheet'!$B$8:$AF$192,31,FALSE) -> -0.96774194
A3: Apr 2026 | B3: Ajit Yadav (Lalmani Yadav) | C3: New | D3: H | E3: Tori | F3: 30 | G3: 15 | H3: 15 | I3: =VLOOKUP(B3,'[1]Wages Sheet'!$B$8:$J$192,9,FALSE) -> 2 | J3: =SUM(VLOOKUP(B3,'[1]Wages Sheet'!$B$8:$K$192,10,FALSE)+(VLOOKUP(B3,'[1]Wages Sheet'!$B$8:$L$192,11,FALSE))) -> 8 | K3: =VLOOKUP(B3,'[1]Wages Sheet'!$B$8:$O$192,14,FALSE) -> 0 | L3: =VLOOKUP(B3,'[1]Wages Sheet'!$B$8:$Q$192,16,FALSE) -> 0 | M3: =VLOOKUP(B3,'[1]Wages Sheet'!$B$8:$T$193,19,FALSE) -> 9500 | N3: =VLOOKUP(B3,'[1]Wages Sheet'!$B$8:$U$192,20,FALSE) -> 7916.6667 | O3: =VLOOKUP(B3,'[1]Wages Sheet'!$B$8:$W$192,22,FALSE) -> 0 | P3: =VLOOKUP(B3,'[1]Wages Sheet'!$B$8:$Z$192,25,FALSE) -> 9500 | Q3: =VLOOKUP(B3,'[1]Wages Sheet'!$B$8:$AD$192,28,FALSE) -> 17416.667 | R3: =VLOOKUP(B3,'[1]Wages Sheet'!$B$8:$AD$192,29,FALSE) -> 17500 | S3: =VLOOKUP(B3,'[1]Wages Sheet'!$B$8:$AF$192,31,FALSE) -> -83.333333
A4: Apr 2026 | B4: Akash Kumar Turi | C4: New | D4: H | F4: 30 | G4: 0 | H4: 30 | I4: =VLOOKUP(B4,'[1]Wages Sheet'!$B$8:$J$192,9,FALSE) -> 0 | J4: =SUM(VLOOKUP(B4,'[1]Wages Sheet'!$B$8:$K$192,10,FALSE)+(VLOOKUP(B4,'[1]Wages Sheet'!$B$8:$L$192,11,FALSE))) -> 0 | K4: =VLOOKUP(B4,'[1]Wages Sheet'!$B$8:$O$192,14,FALSE) -> 0 | L4: =VLOOKUP(B4,'[1]Wages Sheet'!$B$8:$Q$192,16,FALSE) -> 0 | M4: =VLOOKUP(B4,'[1]Wages Sheet'!$B$8:$T$193,19,FALSE) -> 9500 | N4: =VLOOKUP(B4,'[1]Wages Sheet'!$B$8:$U$192,20,FALSE) -> 0 | O4: =VLOOKUP(B4,'[1]Wages Sheet'!$B$8:$W$192,22,FALSE) -> 0 | P4: =VLOOKUP(B4,'[1]Wages Sheet'!$B$8:$Z$192,25,FALSE) -> 0 | Q4: =VLOOKUP(B4,'[1]Wages Sheet'!$B$8:$AD$192,28,FALSE) -> 0 | R4: =VLOOKUP(B4,'[1]Wages Sheet'!$B$8:$AD$192,29,FALSE) -> 0 | S4: =VLOOKUP(B4,'[1]Wages Sheet'!$B$8:$AF$192,31,FALSE) -> 0
A5: Apr 2026 | B5: Amar Lal Mahto | C5: New | D5: T/D | F5: 30 | G5: 0 | H5: 30 | I5: =VLOOKUP(B5,'[1]Wages Sheet'!$B$8:$J$192,9,FALSE) -> 0 | J5: =SUM(VLOOKUP(B5,'[1]Wages Sheet'!$B$8:$K$192,10,FALSE)+(VLOOKUP(B5,'[1]Wages Sheet'!$B$8:$L$192,11,FALSE))) -> 0 | K5: =VLOOKUP(B5,'[1]Wages Sheet'!$B$8:$O$192,14,FALSE) -> 0 | L5: =VLOOKUP(B5,'[1]Wages Sheet'!$B$8:$Q$192,16,FALSE) -> 0 | M5: =VLOOKUP(B5,'[1]Wages Sheet'!$B$8:$T$193,19,FALSE) -> 16000 | N5: =VLOOKUP(B5,'[1]Wages Sheet'!$B$8:$U$192,20,FALSE) -> 0 | O5: =VLOOKUP(B5,'[1]Wages Sheet'!$B$8:$W$192,22,FALSE) -> 0 | P5: =VLOOKUP(B5,'[1]Wages Sheet'!$B$8:$Z$192,25,FALSE) -> 0 | Q5: =VLOOKUP(B5,'[1]Wages Sheet'!$B$8:$AD$192,28,FALSE) -> 0 | R5: =VLOOKUP(B5,'[1]Wages Sheet'!$B$8:$AD$192,29,FALSE) -> 0 | S5: =VLOOKUP(B5,'[1]Wages Sheet'!$B$8:$AF$192,31,FALSE) -> 0
A6: Apr 2026 | B6: Anil Hansda | C6: Old | D6: T/D | E6: Karo/Lalpania | F6: 30 | G6: 19 | H6: 11 | I6: =VLOOKUP(B6,'[1]Wages Sheet'!$B$8:$J$192,9,FALSE) -> -3 | J6: =SUM(VLOOKUP(B6,'[1]Wages Sheet'!$B$8:$K$192,10,FALSE)+(VLOOKUP(B6,'[1]Wages Sheet'!$B$8:$L$192,11,FALSE))) -> 2 | K6: =VLOOKUP(B6,'[1]Wages Sheet'!$B$8:$O$192,14,FALSE) -> 2 | L6: =VLOOKUP(B6,'[1]Wages Sheet'!$B$8:$Q$192,16,FALSE) -> 0 | M6: =VLOOKUP(B6,'[1]Wages Sheet'!$B$8:$T$193,19,FALSE) -> 16000 | N6: =VLOOKUP(B6,'[1]Wages Sheet'!$B$8:$U$192,20,FALSE) -> 11200 | O6: =VLOOKUP(B6,'[1]Wages Sheet'!$B$8:$W$192,22,FALSE) -> 5096.957 | P6: =VLOOKUP(B6,'[1]Wages Sheet'!$B$8:$Z$192,25,FALSE) -> 0 | Q6: =VLOOKUP(B6,'[1]Wages Sheet'!$B$8:$AD$192,28,FALSE) -> 6103.043 | R6: =VLOOKUP(B6,'[1]Wages Sheet'!$B$8:$AD$192,29,FALSE) -> 6103 | S6: =VLOOKUP(B6,'[1]Wages Sheet'!$B$8:$AF$192,31,FALSE) -> 0.043010753
A7: Apr 2026 | B7: Aniruddha Paul | C7: New | D7: ENGG. | E7: Karo | F7: 30 | G7: 28 | H7: 2 | I7: =VLOOKUP(B7,'[1]Wages Sheet'!$B$8:$J$192,9,FALSE) -> -7 | J7: =SUM(VLOOKUP(B7,'[1]Wages Sheet'!$B$8:$K$192,10,FALSE)+(VLOOKUP(B7,'[1]Wages Sheet'!$B$8:$L$192,11,FALSE))) -> 4 | K7: =VLOOKUP(B7,'[1]Wages Sheet'!$B$8:$O$192,14,FALSE) -> 2 | L7: =VLOOKUP(B7,'[1]Wages Sheet'!$B$8:$Q$192,16,FALSE) -> 2 | M7: =VLOOKUP(B7,'[1]Wages Sheet'!$B$8:$T$193,19,FALSE) -> 17000 | N7: =VLOOKUP(B7,'[1]Wages Sheet'!$B$8:$U$192,20,FALSE) -> 17000 | O7: =VLOOKUP(B7,'[1]Wages Sheet'!$B$8:$W$192,22,FALSE) -> 0 | P7: =VLOOKUP(B7,'[1]Wages Sheet'!$B$8:$Z$192,25,FALSE) -> 0 | Q7: =VLOOKUP(B7,'[1]Wages Sheet'!$B$8:$AD$192,28,FALSE) -> 17000 | R7: =VLOOKUP(B7,'[1]Wages Sheet'!$B$8:$AD$192,29,FALSE) -> 17000 | S7: =VLOOKUP(B7,'[1]Wages Sheet'!$B$8:$AF$192,31,FALSE) -> 0
A8: Apr 2026 | B8: Anshu Karmali | C8: New | D8: Polc. H | E8: Karo/ Tori | F8: 30 | G8: 30 | H8: 0 | I8: =VLOOKUP(B8,'[1]Wages Sheet'!$B$8:$J$192,9,FALSE) -> 5 | J8: =SUM(VLOOKUP(B8,'[1]Wages Sheet'!$B$8:$K$192,10,FALSE)+(VLOOKUP(B8,'[1]Wages Sheet'!$B$8:$L$192,11,FALSE))) -> 4 | K8: =VLOOKUP(B8,'[1]Wages Sheet'!$B$8:$O$192,14,FALSE) -> 0 | L8: =VLOOKUP(B8,'[1]Wages Sheet'!$B$8:$Q$192,16,FALSE) -> 9 | M8: =VLOOKUP(B8,'[1]Wages Sheet'!$B$8:$T$193,19,FALSE) -> 9500 | N8: =VLOOKUP(B8,'[1]Wages Sheet'!$B$8:$U$192,20,FALSE) -> 9500 | O8: =VLOOKUP(B8,'[1]Wages Sheet'!$B$8:$W$192,22,FALSE) -> 0 | P8: =VLOOKUP(B8,'[1]Wages Sheet'!$B$8:$Z$192,25,FALSE) -> 9000.3333 | Q8: =VLOOKUP(B8,'[1]Wages Sheet'!$B$8:$AD$192,28,FALSE) -> 18500.333 | R8: =VLOOKUP(B8,'[1]Wages Sheet'!$B$8:$AD$192,29,FALSE) -> 18500 | S8: =VLOOKUP(B8,'[1]Wages Sheet'!$B$8:$AF$192,31,FALSE) -> 0.33333333
A9: Apr 2026 | B9: Arijit Kundu | C9: New | D9: ENGG. | E9: Karo | F9: 30 | G9: 24 | H9: 6 | I9: =VLOOKUP(B9,'[1]Wages Sheet'!$B$8:$J$192,9,FALSE) -> -13 | J9: =SUM(VLOOKUP(B9,'[1]Wages Sheet'!$B$8:$K$192,10,FALSE)+(VLOOKUP(B9,'[1]Wages Sheet'!$B$8:$L$192,11,FALSE))) -> 6 | K9: =VLOOKUP(B9,'[1]Wages Sheet'!$B$8:$O$192,14,FALSE) -> 6 | L9: =VLOOKUP(B9,'[1]Wages Sheet'!$B$8:$Q$192,16,FALSE) -> 0 | M9: =VLOOKUP(B9,'[1]Wages Sheet'!$B$8:$T$193,19,FALSE) -> 18000 | N9: =VLOOKUP(B9,'[1]Wages Sheet'!$B$8:$U$192,20,FALSE) -> 18000 | O9: =VLOOKUP(B9,'[1]Wages Sheet'!$B$8:$W$192,22,FALSE) -> 0 | P9: =VLOOKUP(B9,'[1]Wages Sheet'!$B$8:$Z$192,25,FALSE) -> 0 | Q9: =VLOOKUP(B9,'[1]Wages Sheet'!$B$8:$AD$192,28,FALSE) -> 18000 | R9: =VLOOKUP(B9,'[1]Wages Sheet'!$B$8:$AD$192,29,FALSE) -> 18000 | S9: =VLOOKUP(B9,'[1]Wages Sheet'!$B$8:$AF$192,31,FALSE) -> 0
A10: Apr 2026 | B10: Arpan Lakra | C10: New | D10: H | F10: 30 | G10: 0 | H10: 30 | I10: =VLOOKUP(B10,'[1]Wages Sheet'!$B$8:$J$192,9,FALSE) -> 0 | J10: =SUM(VLOOKUP(B10,'[1]Wages Sheet'!$B$8:$K$192,10,FALSE)+(VLOOKUP(B10,'[1]Wages Sheet'!$B$8:$L$192,11,FALSE))) -> 0 | K10: =VLOOKUP(B10,'[1]Wages Sheet'!$B$8:$O$192,14,FALSE) -> 0 | L10: =VLOOKUP(B10,'[1]Wages Sheet'!$B$8:$Q$192,16,FALSE) -> 0 | M10: =VLOOKUP(B10,'[1]Wages Sheet'!$B$8:$T$193,19,FALSE) -> 8500 | N10: =VLOOKUP(B10,'[1]Wages Sheet'!$B$8:$U$192,20,FALSE) -> 0 | O10: =VLOOKUP(B10,'[1]Wages Sheet'!$B$8:$W$192,22,FALSE) -> 0 | P10: =VLOOKUP(B10,'[1]Wages Sheet'!$B$8:$Z$192,25,FALSE) -> 0 | Q10: =VLOOKUP(B10,'[1]Wages Sheet'!$B$8:$AD$192,28,FALSE) -> 0 | R10: =VLOOKUP(B10,'[1]Wages Sheet'!$B$8:$AD$192,29,FALSE) -> 0 | S10: =VLOOKUP(B10,'[1]Wages Sheet'!$B$8:$AF$192,31,FALSE) -> 0
A11: Apr 2026 | B11: Arun Soren | C11: New | D11: H | F11: 30 | G11: 0 | H11: 30 | I11: =VLOOKUP(B11,'[1]Wages Sheet'!$B$8:$J$192,9,FALSE) -> 0 | J11: =SUM(VLOOKUP(B11,'[1]Wages Sheet'!$B$8:$K$192,10,FALSE)+(VLOOKUP(B11,'[1]Wages Sheet'!$B$8:$L$192,11,FALSE))) -> 0 | K11: =VLOOKUP(B11,'[1]Wages Sheet'!$B$8:$O$192,14,FALSE) -> 0 | L11: =VLOOKUP(B11,'[1]Wages Sheet'!$B$8:$Q$192,16,FALSE) -> 0 | M11: =VLOOKUP(B11,'[1]Wages Sheet'!$B$8:$T$193,19,FALSE) -> 9500 | N11: =VLOOKUP(B11,'[1]Wages Sheet'!$B$8:$U$192,20,FALSE) -> 0 | O11: =VLOOKUP(B11,'[1]Wages Sheet'!$B$8:$W$192,22,FALSE) -> 0 | P11: =VLOOKUP(B11,'[1]Wages Sheet'!$B$8:$Z$192,25,FALSE) -> 7528.8172 | Q11: =VLOOKUP(B11,'[1]Wages Sheet'!$B$8:$AD$192,28,FALSE) -> 7528.8172 | R11: =VLOOKUP(B11,'[1]Wages Sheet'!$B$8:$AD$192,29,FALSE) -> 0 | S11: =VLOOKUP(B11,'[1]Wages Sheet'!$B$8:$AF$192,31,FALSE) -> 7528.8172
A12: Apr 2026 | B12: Aryan Kumar | C12: New | D12: supervisor | F12: 30 | G12: 0 | H12: 30 | I12: =VLOOKUP(B12,'[1]Wages Sheet'!$B$8:$J$192,9,FALSE) -> 0 | J12: =SUM(VLOOKUP(B12,'[1]Wages Sheet'!$B$8:$K$192,10,FALSE)+(VLOOKUP(B12,'[1]Wages Sheet'!$B$8:$L$192,11,FALSE))) -> 0 | K12: =VLOOKUP(B12,'[1]Wages Sheet'!$B$8:$O$192,14,FALSE) -> 0 | L12: =VLOOKUP(B12,'[1]Wages Sheet'!$B$8:$Q$192,16,FALSE) -> 0 | M12: =VLOOKUP(B12,'[1]Wages Sheet'!$B$8:$T$193,19,FALSE) -> 10000 | N12: =VLOOKUP(B12,'[1]Wages Sheet'!$B$8:$U$192,20,FALSE) -> 0 | O12: =VLOOKUP(B12,'[1]Wages Sheet'!$B$8:$W$192,22,FALSE) -> 0 | P12: =VLOOKUP(B12,'[1]Wages Sheet'!$B$8:$Z$192,25,FALSE) -> 0 | Q12: =VLOOKUP(B12,'[1]Wages Sheet'!$B$8:$AD$192,28,FALSE) -> 0 | R12: =VLOOKUP(B12,'[1]Wages Sheet'!$B$8:$AD$192,29,FALSE) -> 0 | S12: =VLOOKUP(B12,'[1]Wages Sheet'!$B$8:$AF$192,31,FALSE) -> 0
A13: Apr 2026 | B13: Ashish Kr. Mahto | C13: New | D13: H | F13: 30 | G13: 0 | H13: 30 | I13: =VLOOKUP(B13,'[1]Wages Sheet'!$B$8:$J$192,9,FALSE) -> 0 | J13: =SUM(VLOOKUP(B13,'[1]Wages Sheet'!$B$8:$K$192,10,FALSE)+(VLOOKUP(B13,'[1]Wages Sheet'!$B$8:$L$192,11,FALSE))) -> 0 | K13: =VLOOKUP(B13,'[1]Wages Sheet'!$B$8:$O$192,14,FALSE) -> 0 | L13: =VLOOKUP(B13,'[1]Wages Sheet'!$B$8:$Q$192,16,FALSE) -> 0 | M13: =VLOOKUP(B13,'[1]Wages Sheet'!$B$8:$T$193,19,FALSE) -> 9500 | N13: =VLOOKUP(B13,'[1]Wages Sheet'!$B$8:$U$192,20,FALSE) -> 0 | O13: =VLOOKUP(B13,'[1]Wages Sheet'!$B$8:$W$192,22,FALSE) -> 0 | P13: =VLOOKUP(B13,'[1]Wages Sheet'!$B$8:$Z$192,25,FALSE) -> 0 | Q13: =VLOOKUP(B13,'[1]Wages Sheet'!$B$8:$AD$192,28,FALSE) -> 0 | R13: =VLOOKUP(B13,'[1]Wages Sheet'!$B$8:$AD$192,29,FALSE) -> 0 | S13: =VLOOKUP(B13,'[1]Wages Sheet'!$B$8:$AF$192,31,FALSE) -> 0
A14: Apr 2026 | B14: Bablu Hembrom | C14: New | D14: T/D | E14: Karo/lalpania | F14: 30 | G14: 22 | H14: 8 | I14: =VLOOKUP(B14,'[1]Wages Sheet'!$B$8:$J$192,9,FALSE) -> -3 | J14: =SUM(VLOOKUP(B14,'[1]Wages Sheet'!$B$8:$K$192,10,FALSE)+(VLOOKUP(B14,'[1]Wages Sheet'!$B$8:$L$192,11,FALSE))) -> 8 | K14: =VLOOKUP(B14,'[1]Wages Sheet'!$B$8:$O$192,14,FALSE) -> 8 | L14: =VLOOKUP(B14,'[1]Wages Sheet'!$B$8:$Q$192,16,FALSE) -> 0 | M14: =VLOOKUP(B14,'[1]Wages Sheet'!$B$8:$T$193,19,FALSE) -> 16000 | N14: =VLOOKUP(B14,'[1]Wages Sheet'!$B$8:$U$192,20,FALSE) -> 16000 | O14: =VLOOKUP(B14,'[1]Wages Sheet'!$B$8:$W$192,22,FALSE) -> 1109.8172 | P14: =VLOOKUP(B14,'[1]Wages Sheet'!$B$8:$Z$192,25,FALSE) -> 0 | Q14: =VLOOKUP(B14,'[1]Wages Sheet'!$B$8:$AD$192,28,FALSE) -> 14890.183 | R14: =VLOOKUP(B14,'[1]Wages Sheet'!$B$8:$AD$192,29,FALSE) -> 14890 | S14: =VLOOKUP(B14,'[1]Wages Sheet'!$B$8:$AF$192,31,FALSE) -> 0.1827957
A15: Apr 2026 | B15: Babu Murmu | C15: Old | D15: MECHANIC | E15: Karo/Tori/Lal | F15: 30 | G15: 29 | H15: 1 | I15: =VLOOKUP(B15,'[1]Wages Sheet'!$B$8:$J$192,9,FALSE) -> -4 | J15: =SUM(VLOOKUP(B15,'[1]Wages Sheet'!$B$8:$K$192,10,FALSE)+(VLOOKUP(B15,'[1]Wages Sheet'!$B$8:$L$192,11,FALSE))) -> 4 | K15: =VLOOKUP(B15,'[1]Wages Sheet'!$B$8:$O$192,14,FALSE) -> 1 | L15: =VLOOKUP(B15,'[1]Wages Sheet'!$B$8:$Q$192,16,FALSE) -> 3 | M15: =VLOOKUP(B15,'[1]Wages Sheet'!$B$8:$T$193,19,FALSE) -> 17000 | N15: =VLOOKUP(B15,'[1]Wages Sheet'!$B$8:$U$192,20,FALSE) -> 17000 | O15: =VLOOKUP(B15,'[1]Wages Sheet'!$B$8:$W$192,22,FALSE) -> 0 | P15: =VLOOKUP(B15,'[1]Wages Sheet'!$B$8:$Z$192,25,FALSE) -> 5806.4516 | Q15: =VLOOKUP(B15,'[1]Wages Sheet'!$B$8:$AD$192,28,FALSE) -> 22806.452 | R15: =VLOOKUP(B15,'[1]Wages Sheet'!$B$8:$AD$192,29,FALSE) -> 23306 | S15: =VLOOKUP(B15,'[1]Wages Sheet'!$B$8:$AF$192,31,FALSE) -> -499.54839
A16: Apr 2026 | B16: Babu Rajwar | C16: Old | D16: P.Foreman | E16: Karo | F16: 30 | G16: 29 | H16: 1 | I16: =VLOOKUP(B16,'[1]Wages Sheet'!$B$8:$J$192,9,FALSE) -> 8 | J16: =SUM(VLOOKUP(B16,'[1]Wages Sheet'!$B$8:$K$192,10,FALSE)+(VLOOKUP(B16,'[1]Wages Sheet'!$B$8:$L$192,11,FALSE))) -> 4 | K16: =VLOOKUP(B16,'[1]Wages Sheet'!$B$8:$O$192,14,FALSE) -> 1 | L16: =VLOOKUP(B16,'[1]Wages Sheet'!$B$8:$Q$192,16,FALSE) -> 11 | M16: =VLOOKUP(B16,'[1]Wages Sheet'!$B$8:$T$193,19,FALSE) -> 21000 | N16: =VLOOKUP(B16,'[1]Wages Sheet'!$B$8:$U$192,20,FALSE) -> 21000 | O16: =VLOOKUP(B16,'[1]Wages Sheet'!$B$8:$W$192,22,FALSE) -> 0 | P16: =VLOOKUP(B16,'[1]Wages Sheet'!$B$8:$Z$192,25,FALSE) -> 0 | Q16: =VLOOKUP(B16,'[1]Wages Sheet'!$B$8:$AD$192,28,FALSE) -> 21000 | R16: =VLOOKUP(B16,'[1]Wages Sheet'!$B$8:$AD$192,29,FALSE) -> 21000 | S16: =VLOOKUP(B16,'[1]Wages Sheet'!$B$8:$AF$192,31,FALSE) -> 0
A17: Apr 2026 | B17: Baldeo Rajak | C17: Old | D17: T/D | E17: Karo/tori | F17: 30 | G17: 28 | H17: 2 | I17: =VLOOKUP(B17,'[1]Wages Sheet'!$B$8:$J$192,9,FALSE) -> 3 | J17: =SUM(VLOOKUP(B17,'[1]Wages Sheet'!$B$8:$K$192,10,FALSE)+(VLOOKUP(B17,'[1]Wages Sheet'!$B$8:$L$192,11,FALSE))) -> 4 | K17: =VLOOKUP(B17,'[1]Wages Sheet'!$B$8:$O$192,14,FALSE) -> 2 | L17: =VLOOKUP(B17,'[1]Wages Sheet'!$B$8:$Q$192,16,FALSE) -> 5 | M17: =VLOOKUP(B17,'[1]Wages Sheet'!$B$8:$T$193,19,FALSE) -> 16000 | N17: =VLOOKUP(B17,'[1]Wages Sheet'!$B$8:$U$192,20,FALSE) -> 16000 | O17: =VLOOKUP(B17,'[1]Wages Sheet'!$B$8:$W$192,22,FALSE) -> 0 | P17: =VLOOKUP(B17,'[1]Wages Sheet'!$B$8:$Z$192,25,FALSE) -> 16000 | Q17: =VLOOKUP(B17,'[1]Wages Sheet'!$B$8:$AD$192,28,FALSE) -> 32000 | R17: =VLOOKUP(B17,'[1]Wages Sheet'!$B$8:$AD$192,29,FALSE) -> 32000 | S17: =VLOOKUP(B17,'[1]Wages Sheet'!$B$8:$AF$192,31,FALSE) -> 0
A18: Apr 2026 | B18: Baldeo Yadav | C18: New | D18: supervisor | F18: 30 | G18: 0 | H18: 30 | I18: =VLOOKUP(B18,'[1]Wages Sheet'!$B$8:$J$192,9,FALSE) -> 0 | J18: =SUM(VLOOKUP(B18,'[1]Wages Sheet'!$B$8:$K$192,10,FALSE)+(VLOOKUP(B18,'[1]Wages Sheet'!$B$8:$L$192,11,FALSE))) -> 0 | K18: =VLOOKUP(B18,'[1]Wages Sheet'!$B$8:$O$192,14,FALSE) -> 0 | L18: =VLOOKUP(B18,'[1]Wages Sheet'!$B$8:$Q$192,16,FALSE) -> 0 | M18: =VLOOKUP(B18,'[1]Wages Sheet'!$B$8:$T$193,19,FALSE) -> 9000 | N18: =VLOOKUP(B18,'[1]Wages Sheet'!$B$8:$U$192,20,FALSE) -> 0 | O18: =VLOOKUP(B18,'[1]Wages Sheet'!$B$8:$W$192,22,FALSE) -> 0 | P18: =VLOOKUP(B18,'[1]Wages Sheet'!$B$8:$Z$192,25,FALSE) -> 0 | Q18: =VLOOKUP(B18,'[1]Wages Sheet'!$B$8:$AD$192,28,FALSE) -> 0 | R18: =VLOOKUP(B18,'[1]Wages Sheet'!$B$8:$AD$192,29,FALSE) -> 0 | S18: =VLOOKUP(B18,'[1]Wages Sheet'!$B$8:$AF$192,31,FALSE) -> 0
A19: Apr 2026 | B19: Banty Thakur | C19: New | D19: H | F19: 30 | G19: 0 | H19: 30 | I19: =VLOOKUP(B19,'[1]Wages Sheet'!$B$8:$J$192,9,FALSE) -> 0 | J19: =SUM(VLOOKUP(B19,'[1]Wages Sheet'!$B$8:$K$192,10,FALSE)+(VLOOKUP(B19,'[1]Wages Sheet'!$B$8:$L$192,11,FALSE))) -> 0 | K19: =VLOOKUP(B19,'[1]Wages Sheet'!$B$8:$O$192,14,FALSE) -> 0 | L19: =VLOOKUP(B19,'[1]Wages Sheet'!$B$8:$Q$192,16,FALSE) -> 0 | M19: =VLOOKUP(B19,'[1]Wages Sheet'!$B$8:$T$193,19,FALSE) -> 9500 | N19: =VLOOKUP(B19,'[1]Wages Sheet'!$B$8:$U$192,20,FALSE) -> 0 | O19: =VLOOKUP(B19,'[1]Wages Sheet'!$B$8:$W$192,22,FALSE) -> 0 | P19: =VLOOKUP(B19,'[1]Wages Sheet'!$B$8:$Z$192,25,FALSE) -> 0 | Q19: =VLOOKUP(B19,'[1]Wages Sheet'!$B$8:$AD$192,28,FALSE) -> 0 | R19: =VLOOKUP(B19,'[1]Wages Sheet'!$B$8:$AD$192,29,FALSE) -> 0 | S19: =VLOOKUP(B19,'[1]Wages Sheet'!$B$8:$AF$192,31,FALSE) -> 0
A20: Apr 2026 | B20: Basu Sawarnkar | C20: New | D20: COOK | E20: konar | F20: 30 | G20: 30 | H20: 0 | I20: =VLOOKUP(B20,'[1]Wages Sheet'!$B$8:$J$192,9,FALSE) -> 9 | J20: =SUM(VLOOKUP(B20,'[1]Wages Sheet'!$B$8:$K$192,10,FALSE)+(VLOOKUP(B20,'[1]Wages Sheet'!$B$8:$L$192,11,FALSE))) -> 4 | K20: =VLOOKUP(B20,'[1]Wages Sheet'!$B$8:$O$192,14,FALSE) -> 0 | L20: =VLOOKUP(B20,'[1]Wages Sheet'!$B$8:$Q$192,16,FALSE) -> 13 | M20: =VLOOKUP(B20,'[1]Wages Sheet'!$B$8:$T$193,19,FALSE) -> 11000 | N20: =VLOOKUP(B20,'[1]Wages Sheet'!$B$8:$U$192,20,FALSE) -> 11000 | O20: =VLOOKUP(B20,'[1]Wages Sheet'!$B$8:$W$192,22,FALSE) -> 0 | P20: =VLOOKUP(B20,'[1]Wages Sheet'!$B$8:$Z$192,25,FALSE) -> 5988.7097 | Q20: =VLOOKUP(B20,'[1]Wages Sheet'!$B$8:$AD$192,28,FALSE) -> 16988.71 | R20: =VLOOKUP(B20,'[1]Wages Sheet'!$B$8:$AD$192,29,FALSE) -> 17000 | S20: =VLOOKUP(B20,'[1]Wages Sheet'!$B$8:$AF$192,31,FALSE) -> -11.290323
A21: Apr 2026 | B21: Bhavishay Tiwari | C21: New | D21: T/D | F21: 30 | G21: 0 | H21: 30 | I21: =VLOOKUP(B21,'[1]Wages Sheet'!$B$8:$J$192,9,FALSE) -> 0 | J21: =SUM(VLOOKUP(B21,'[1]Wages Sheet'!$B$8:$K$192,10,FALSE)+(VLOOKUP(B21,'[1]Wages Sheet'!$B$8:$L$192,11,FALSE))) -> 0 | K21: =VLOOKUP(B21,'[1]Wages Sheet'!$B$8:$O$192,14,FALSE) -> 0 | L21: =VLOOKUP(B21,'[1]Wages Sheet'!$B$8:$Q$192,16,FALSE) -> 0 | M21: =VLOOKUP(B21,'[1]Wages Sheet'!$B$8:$T$193,19,FALSE) -> 15500 | N21: =VLOOKUP(B21,'[1]Wages Sheet'!$B$8:$U$192,20,FALSE) -> 0 | O21: =VLOOKUP(B21,'[1]Wages Sheet'!$B$8:$W$192,22,FALSE) -> 0 | P21: =VLOOKUP(B21,'[1]Wages Sheet'!$B$8:$Z$192,25,FALSE) -> 0 | Q21: =VLOOKUP(B21,'[1]Wages Sheet'!$B$8:$AD$192,28,FALSE) -> 0 | R21: =VLOOKUP(B21,'[1]Wages Sheet'!$B$8:$AD$192,29,FALSE) -> 0 | S21: =VLOOKUP(B21,'[1]Wages Sheet'!$B$8:$AF$192,31,FALSE) -> 0
A22: Apr 2026 | B22: Bhola Mahto (Td) | C22: Old | D22: T/D | E22: lal | F22: 30 | G22: 30 | H22: 0 | I22: =VLOOKUP(B22,'[1]Wages Sheet'!$B$8:$J$192,9,FALSE) -> 1 | J22: =SUM(VLOOKUP(B22,'[1]Wages Sheet'!$B$8:$K$192,10,FALSE)+(VLOOKUP(B22,'[1]Wages Sheet'!$B$8:$L$192,11,FALSE))) -> 4 | K22: =VLOOKUP(B22,'[1]Wages Sheet'!$B$8:$O$192,14,FALSE) -> 0 | L22: =VLOOKUP(B22,'[1]Wages Sheet'!$B$8:$Q$192,16,FALSE) -> 5 | M22: =VLOOKUP(B22,'[1]Wages Sheet'!$B$8:$T$193,19,FALSE) -> 16000 | N22: =VLOOKUP(B22,'[1]Wages Sheet'!$B$8:$U$192,20,FALSE) -> 16000 | O22: =VLOOKUP(B22,'[1]Wages Sheet'!$B$8:$W$192,22,FALSE) -> 0 | P22: =VLOOKUP(B22,'[1]Wages Sheet'!$B$8:$Z$192,25,FALSE) -> 8011.6129 | Q22: =VLOOKUP(B22,'[1]Wages Sheet'!$B$8:$AD$192,28,FALSE) -> 24011.613 | R22: =VLOOKUP(B22,'[1]Wages Sheet'!$B$8:$AD$192,29,FALSE) -> 24012 | S22: =VLOOKUP(B22,'[1]Wages Sheet'!$B$8:$AF$192,31,FALSE) -> -0.38709677
A23: Apr 2026 | B23: Bhola Mahto (Polc.H) | C23: New | D23: Polc. H | E23: Karo | F23: 30 | G23: 26 | H23: 4 | I23: =VLOOKUP(B23,'[1]Wages Sheet'!$B$8:$J$192,9,FALSE) -> 3 | J23: =SUM(VLOOKUP(B23,'[1]Wages Sheet'!$B$8:$K$192,10,FALSE)+(VLOOKUP(B23,'[1]Wages Sheet'!$B$8:$L$192,11,FALSE))) -> 4 | K23: =VLOOKUP(B23,'[1]Wages Sheet'!$B$8:$O$192,14,FALSE) -> 4 | L23: =VLOOKUP(B23,'[1]Wages Sheet'!$B$8:$Q$192,16,FALSE) -> 3 | M23: =VLOOKUP(B23,'[1]Wages Sheet'!$B$8:$T$193,19,FALSE) -> 9500 | N23: =VLOOKUP(B23,'[1]Wages Sheet'!$B$8:$U$192,20,FALSE) -> 9500 | O23: =VLOOKUP(B23,'[1]Wages Sheet'!$B$8:$W$192,22,FALSE) -> 0 | P23: =VLOOKUP(B23,'[1]Wages Sheet'!$B$8:$Z$192,25,FALSE) -> 9496.6667 | Q23: =VLOOKUP(B23,'[1]Wages Sheet'!$B$8:$AD$192,28,FALSE) -> 18996.667 | R23: =VLOOKUP(B23,'[1]Wages Sheet'!$B$8:$AD$192,29,FALSE) -> 19000 | S23: =VLOOKUP(B23,'[1]Wages Sheet'!$B$8:$AF$192,31,FALSE) -> -3.3333333
A24: Apr 2026 | B24: Bipin Kumar (Rajak) | C24: Local | D24: T/D | F24: 30 | G24: 0 | H24: 30 | I24: =VLOOKUP(B24,'[1]Wages Sheet'!$B$8:$J$192,9,FALSE) -> 0 | J24: =SUM(VLOOKUP(B24,'[1]Wages Sheet'!$B$8:$K$192,10,FALSE)+(VLOOKUP(B24,'[1]Wages Sheet'!$B$8:$L$192,11,FALSE))) -> 0 | K24: =VLOOKUP(B24,'[1]Wages Sheet'!$B$8:$O$192,14,FALSE) -> 0 | L24: =VLOOKUP(B24,'[1]Wages Sheet'!$B$8:$Q$192,16,FALSE) -> 0 | M24: =VLOOKUP(B24,'[1]Wages Sheet'!$B$8:$T$193,19,FALSE) -> 16000 | N24: =VLOOKUP(B24,'[1]Wages Sheet'!$B$8:$U$192,20,FALSE) -> 0 | O24: =VLOOKUP(B24,'[1]Wages Sheet'!$B$8:$W$192,22,FALSE) -> 0.35483871 | P24: =VLOOKUP(B24,'[1]Wages Sheet'!$B$8:$Z$192,25,FALSE) -> 0 | Q24: =VLOOKUP(B24,'[1]Wages Sheet'!$B$8:$AD$192,28,FALSE) -> -0.35483871 | R24: =VLOOKUP(B24,'[1]Wages Sheet'!$B$8:$AD$192,29,FALSE) -> 0 | S24: =VLOOKUP(B24,'[1]Wages Sheet'!$B$8:$AF$192,31,FALSE) -> -0.35483871
A25: Apr 2026 | B25: Birendra Kr. Prasad | C25: New | D25: supervisor | E25: Lal | F25: 30 | G25: 30 | H25: 0 | I25: =VLOOKUP(B25,'[1]Wages Sheet'!$B$8:$J$192,9,FALSE) -> 11 | J25: =SUM(VLOOKUP(B25,'[1]Wages Sheet'!$B$8:$K$192,10,FALSE)+(VLOOKUP(B25,'[1]Wages Sheet'!$B$8:$L$192,11,FALSE))) -> 4 | K25: =VLOOKUP(B25,'[1]Wages Sheet'!$B$8:$O$192,14,FALSE) -> 0 | L25: =VLOOKUP(B25,'[1]Wages Sheet'!$B$8:$Q$192,16,FALSE) -> 15 | M25: =VLOOKUP(B25,'[1]Wages Sheet'!$B$8:$T$193,19,FALSE) -> 13000 | N25: =VLOOKUP(B25,'[1]Wages Sheet'!$B$8:$U$192,20,FALSE) -> 13000 | O25: =VLOOKUP(B25,'[1]Wages Sheet'!$B$8:$W$192,22,FALSE) -> 0 | P25: =VLOOKUP(B25,'[1]Wages Sheet'!$B$8:$Z$192,25,FALSE) -> 8500 | Q25: =VLOOKUP(B25,'[1]Wages Sheet'!$B$8:$AD$192,28,FALSE) -> 21500 | R25: =VLOOKUP(B25,'[1]Wages Sheet'!$B$8:$AD$192,29,FALSE) -> 21500 | S25: =VLOOKUP(B25,'[1]Wages Sheet'!$B$8:$AF$192,31,FALSE) -> 0
A26: Apr 2026 | B26: Birendra Kumar | C26: New | D26: supervisor | F26: 30 | G26: 0 | H26: 30 | I26: =VLOOKUP(B26,'[1]Wages Sheet'!$B$8:$J$192,9,FALSE) -> 0 | J26: =SUM(VLOOKUP(B26,'[1]Wages Sheet'!$B$8:$K$192,10,FALSE)+(VLOOKUP(B26,'[1]Wages Sheet'!$B$8:$L$192,11,FALSE))) -> 0 | K26: =VLOOKUP(B26,'[1]Wages Sheet'!$B$8:$O$192,14,FALSE) -> 0 | L26: =VLOOKUP(B26,'[1]Wages Sheet'!$B$8:$Q$192,16,FALSE) -> 0 | M26: =VLOOKUP(B26,'[1]Wages Sheet'!$B$8:$T$193,19,FALSE) -> 9000 | N26: =VLOOKUP(B26,'[1]Wages Sheet'!$B$8:$U$192,20,FALSE) -> 0 | O26: =VLOOKUP(B26,'[1]Wages Sheet'!$B$8:$W$192,22,FALSE) -> 21 | P26: =VLOOKUP(B26,'[1]Wages Sheet'!$B$8:$Z$192,25,FALSE) -> 0 | Q26: =VLOOKUP(B26,'[1]Wages Sheet'!$B$8:$AD$192,28,FALSE) -> -21 | R26: =VLOOKUP(B26,'[1]Wages Sheet'!$B$8:$AD$192,29,FALSE) -> 0 | S26: =VLOOKUP(B26,'[1]Wages Sheet'!$B$8:$AF$192,31,FALSE) -> -21
A27: Apr 2026 | B27: Budhan Singh | C27: New | D27: N/G | E27: Karo | F27: 30 | G27: 29 | H27: 1 | I27: =VLOOKUP(B27,'[1]Wages Sheet'!$B$8:$J$192,9,FALSE) -> 0 | J27: =SUM(VLOOKUP(B27,'[1]Wages Sheet'!$B$8:$K$192,10,FALSE)+(VLOOKUP(B27,'[1]Wages Sheet'!$B$8:$L$192,11,FALSE))) -> 0 | K27: =VLOOKUP(B27,'[1]Wages Sheet'!$B$8:$O$192,14,FALSE) -> 0 | L27: =VLOOKUP(B27,'[1]Wages Sheet'!$B$8:$Q$192,16,FALSE) -> 0 | M27: =VLOOKUP(B27,'[1]Wages Sheet'!$B$8:$T$193,19,FALSE) -> 9000 | N27: =VLOOKUP(B27,'[1]Wages Sheet'!$B$8:$U$192,20,FALSE) -> 8700 | O27: =VLOOKUP(B27,'[1]Wages Sheet'!$B$8:$W$192,22,FALSE) -> 0 | P27: =VLOOKUP(B27,'[1]Wages Sheet'!$B$8:$Z$192,25,FALSE) -> 9000.637 | Q27: =VLOOKUP(B27,'[1]Wages Sheet'!$B$8:$AD$192,28,FALSE) -> 17700.637 | R27: =VLOOKUP(B27,'[1]Wages Sheet'!$B$8:$AD$192,29,FALSE) -> 17700 | S27: =VLOOKUP(B27,'[1]Wages Sheet'!$B$8:$AF$192,31,FALSE) -> 0.63700461
A28: Apr 2026 | B28: Chandan Kr Mahto | C28: New | D28: JCB.Help | F28: 30 | G28: 0 | H28: 30 | I28: =VLOOKUP(B28,'[1]Wages Sheet'!$B$8:$J$192,9,FALSE) -> 0 | J28: =SUM(VLOOKUP(B28,'[1]Wages Sheet'!$B$8:$K$192,10,FALSE)+(VLOOKUP(B28,'[1]Wages Sheet'!$B$8:$L$192,11,FALSE))) -> 0 | K28: =VLOOKUP(B28,'[1]Wages Sheet'!$B$8:$O$192,14,FALSE) -> 0 | L28: =VLOOKUP(B28,'[1]Wages Sheet'!$B$8:$Q$192,16,FALSE) -> 0 | M28: =VLOOKUP(B28,'[1]Wages Sheet'!$B$8:$T$193,19,FALSE) -> 9500 | N28: =VLOOKUP(B28,'[1]Wages Sheet'!$B$8:$U$192,20,FALSE) -> 0 | O28: =VLOOKUP(B28,'[1]Wages Sheet'!$B$8:$W$192,22,FALSE) -> 0 | P28: =VLOOKUP(B28,'[1]Wages Sheet'!$B$8:$Z$192,25,FALSE) -> 0 | Q28: =VLOOKUP(B28,'[1]Wages Sheet'!$B$8:$AD$192,28,FALSE) -> 0 | R28: =VLOOKUP(B28,'[1]Wages Sheet'!$B$8:$AD$192,29,FALSE) -> 0 | S28: =VLOOKUP(B28,'[1]Wages Sheet'!$B$8:$AF$192,31,FALSE) -> 0
A29: Apr 2026 | B29: Choudhary Charan Mahto | C29: New | D29: T/D | F29: 30 | G29: 0 | H29: 30 | I29: =VLOOKUP(B29,'[1]Wages Sheet'!$B$8:$J$192,9,FALSE) -> 0 | J29: =SUM(VLOOKUP(B29,'[1]Wages Sheet'!$B$8:$K$192,10,FALSE)+(VLOOKUP(B29,'[1]Wages Sheet'!$B$8:$L$192,11,FALSE))) -> 0 | K29: =VLOOKUP(B29,'[1]Wages Sheet'!$B$8:$O$192,14,FALSE) -> 0 | L29: =VLOOKUP(B29,'[1]Wages Sheet'!$B$8:$Q$192,16,FALSE) -> 0 | M29: =VLOOKUP(B29,'[1]Wages Sheet'!$B$8:$T$193,19,FALSE) -> 14500 | N29: =VLOOKUP(B29,'[1]Wages Sheet'!$B$8:$U$192,20,FALSE) -> 0 | O29: =VLOOKUP(B29,'[1]Wages Sheet'!$B$8:$W$192,22,FALSE) -> 0 | P29: =VLOOKUP(B29,'[1]Wages Sheet'!$B$8:$Z$192,25,FALSE) -> 4199.9974 | Q29: =VLOOKUP(B29,'[1]Wages Sheet'!$B$8:$AD$192,28,FALSE) -> 4199.9974 | R29: =VLOOKUP(B29,'[1]Wages Sheet'!$B$8:$AD$192,29,FALSE) -> 0 | S29: =VLOOKUP(B29,'[1]Wages Sheet'!$B$8:$AF$192,31,FALSE) -> 4199.9974
A30: Apr 2026 | B30: Das Nag | C30: New | D30: H | F30: 30 | G30: 0 | H30: 30 | I30: =VLOOKUP(B30,'[1]Wages Sheet'!$B$8:$J$192,9,FALSE) -> 0 | J30: =SUM(VLOOKUP(B30,'[1]Wages Sheet'!$B$8:$K$192,10,FALSE)+(VLOOKUP(B30,'[1]Wages Sheet'!$B$8:$L$192,11,FALSE))) -> 0 | K30: =VLOOKUP(B30,'[1]Wages Sheet'!$B$8:$O$192,14,FALSE) -> 0 | L30: =VLOOKUP(B30,'[1]Wages Sheet'!$B$8:$Q$192,16,FALSE) -> 0 | M30: =VLOOKUP(B30,'[1]Wages Sheet'!$B$8:$T$193,19,FALSE) -> 9500 | N30: =VLOOKUP(B30,'[1]Wages Sheet'!$B$8:$U$192,20,FALSE) -> 0 | O30: =VLOOKUP(B30,'[1]Wages Sheet'!$B$8:$W$192,22,FALSE) -> 0 | P30: =VLOOKUP(B30,'[1]Wages Sheet'!$B$8:$Z$192,25,FALSE) -> 3.7757296 | Q30: =VLOOKUP(B30,'[1]Wages Sheet'!$B$8:$AD$192,28,FALSE) -> 3.7757296 | R30: =VLOOKUP(B30,'[1]Wages Sheet'!$B$8:$AD$192,29,FALSE) -> 0 | S30: =VLOOKUP(B30,'[1]Wages Sheet'!$B$8:$AF$192,31,FALSE) -> 3.7757296
A31: Apr 2026 | B31: Dharmendra Karmali | C31: Old | D31: H | E31: lal | F31: 30 | G31: 22 | H31: 8 | I31: =VLOOKUP(B31,'[1]Wages Sheet'!$B$8:$J$192,9,FALSE) -> -1 | J31: =SUM(VLOOKUP(B31,'[1]Wages Sheet'!$B$8:$K$192,10,FALSE)+(VLOOKUP(B31,'[1]Wages Sheet'!$B$8:$L$192,11,FALSE))) -> 3 | K31: =VLOOKUP(B31,'[1]Wages Sheet'!$B$8:$O$192,14,FALSE) -> 0 | L31: =VLOOKUP(B31,'[1]Wages Sheet'!$B$8:$Q$192,16,FALSE) -> 0 | M31: =VLOOKUP(B31,'[1]Wages Sheet'!$B$8:$T$193,19,FALSE) -> 9500 | N31: =VLOOKUP(B31,'[1]Wages Sheet'!$B$8:$U$192,20,FALSE) -> 7916.6667 | O31: =VLOOKUP(B31,'[1]Wages Sheet'!$B$8:$W$192,22,FALSE) -> 0 | P31: =VLOOKUP(B31,'[1]Wages Sheet'!$B$8:$Z$192,25,FALSE) -> 1270.1935 | Q31: =VLOOKUP(B31,'[1]Wages Sheet'!$B$8:$AD$192,28,FALSE) -> 9186.8602 | R31: =VLOOKUP(B31,'[1]Wages Sheet'!$B$8:$AD$192,29,FALSE) -> 10000 | S31: =VLOOKUP(B31,'[1]Wages Sheet'!$B$8:$AF$192,31,FALSE) -> -813.13978
A32: Apr 2026 | B32: Dharmendra Kr. Tiwari | C32: New | D32: supervisor | E32: Karo | F32: 30 | G32: 26 | H32: 4 | I32: =VLOOKUP(B32,'[1]Wages Sheet'!$B$8:$J$192,9,FALSE) -> -3.5 | J32: =SUM(VLOOKUP(B32,'[1]Wages Sheet'!$B$8:$K$192,10,FALSE)+(VLOOKUP(B32,'[1]Wages Sheet'!$B$8:$L$192,11,FALSE))) -> 4 | K32: =VLOOKUP(B32,'[1]Wages Sheet'!$B$8:$O$192,14,FALSE) -> 4 | L32: =VLOOKUP(B32,'[1]Wages Sheet'!$B$8:$Q$192,16,FALSE) -> 0 | M32: =VLOOKUP(B32,'[1]Wages Sheet'!$B$8:$T$193,19,FALSE) -> 10000 | N32: =VLOOKUP(B32,'[1]Wages Sheet'!$B$8:$U$192,20,FALSE) -> 10000 | O32: =VLOOKUP(B32,'[1]Wages Sheet'!$B$8:$W$192,22,FALSE) -> 0 | P32: =VLOOKUP(B32,'[1]Wages Sheet'!$B$8:$Z$192,25,FALSE) -> 7382.8341 | Q32: =VLOOKUP(B32,'[1]Wages Sheet'!$B$8:$AD$192,28,FALSE) -> 17382.834 | R32: =VLOOKUP(B32,'[1]Wages Sheet'!$B$8:$AD$192,29,FALSE) -> 17400 | S32: =VLOOKUP(B32,'[1]Wages Sheet'!$B$8:$AF$192,31,FALSE) -> -17.165899
A33: Apr 2026 | B33: Dharmveer Kr. | C33: New | D33: D.H | F33: 30 | G33: 0 | H33: 30 | I33: =VLOOKUP(B33,'[1]Wages Sheet'!$B$8:$J$192,9,FALSE) -> 0 | J33: =SUM(VLOOKUP(B33,'[1]Wages Sheet'!$B$8:$K$192,10,FALSE)+(VLOOKUP(B33,'[1]Wages Sheet'!$B$8:$L$192,11,FALSE))) -> 0 | K33: =VLOOKUP(B33,'[1]Wages Sheet'!$B$8:$O$192,14,FALSE) -> 0 | L33: =VLOOKUP(B33,'[1]Wages Sheet'!$B$8:$Q$192,16,FALSE) -> 0 | M33: =VLOOKUP(B33,'[1]Wages Sheet'!$B$8:$T$193,19,FALSE) -> 9000 | N33: =VLOOKUP(B33,'[1]Wages Sheet'!$B$8:$U$192,20,FALSE) -> 0 | O33: =VLOOKUP(B33,'[1]Wages Sheet'!$B$8:$W$192,22,FALSE) -> 0 | P33: =VLOOKUP(B33,'[1]Wages Sheet'!$B$8:$Z$192,25,FALSE) -> 0 | Q33: =VLOOKUP(B33,'[1]Wages Sheet'!$B$8:$AD$192,28,FALSE) -> 0 | R33: =VLOOKUP(B33,'[1]Wages Sheet'!$B$8:$AD$192,29,FALSE) -> 0 | S33: =VLOOKUP(B33,'[1]Wages Sheet'!$B$8:$AF$192,31,FALSE) -> 0
A34: Apr 2026 | B34: Dilip Yadav | C34: New | D34: Polc.Op | E34: Tori | F34: 30 | G34: 22 | H34: 8 | I34: =VLOOKUP(B34,'[1]Wages Sheet'!$B$8:$J$192,9,FALSE) -> 9 | J34: =SUM(VLOOKUP(B34,'[1]Wages Sheet'!$B$8:$K$192,10,FALSE)+(VLOOKUP(B34,'[1]Wages Sheet'!$B$8:$L$192,11,FALSE))) -> 3 | K34: =VLOOKUP(B34,'[1]Wages Sheet'!$B$8:$O$192,14,FALSE) -> 0 | L34: =VLOOKUP(B34,'[1]Wages Sheet'!$B$8:$Q$192,16,FALSE) -> 4 | M34: =VLOOKUP(B34,'[1]Wages Sheet'!$B$8:$T$193,19,FALSE) -> 17000 | N34: =VLOOKUP(B34,'[1]Wages Sheet'!$B$8:$U$192,20,FALSE) -> 17000 | O34: =VLOOKUP(B34,'[1]Wages Sheet'!$B$8:$W$192,22,FALSE) -> 0 | P34: =VLOOKUP(B34,'[1]Wages Sheet'!$B$8:$Z$192,25,FALSE) -> 0 | Q34: =VLOOKUP(B34,'[1]Wages Sheet'!$B$8:$AD$192,28,FALSE) -> 17000 | R34: =VLOOKUP(B34,'[1]Wages Sheet'!$B$8:$AD$192,29,FALSE) -> 17000 | S34: =VLOOKUP(B34,'[1]Wages Sheet'!$B$8:$AF$192,31,FALSE) -> 0
A35: Apr 2026 | B35: Ganesh Singh | C35: New | D35: N/G | E35: Karo | F35: 30 | G35: 28 | H35: 2 | I35: =VLOOKUP(B35,'[1]Wages Sheet'!$B$8:$J$192,9,FALSE) -> 0 | J35: =SUM(VLOOKUP(B35,'[1]Wages Sheet'!$B$8:$K$192,10,FALSE)+(VLOOKUP(B35,'[1]Wages Sheet'!$B$8:$L$192,11,FALSE))) -> 0 | K35: =VLOOKUP(B35,'[1]Wages Sheet'!$B$8:$O$192,14,FALSE) -> 0 | L35: =VLOOKUP(B35,'[1]Wages Sheet'!$B$8:$Q$192,16,FALSE) -> 0 | M35: =VLOOKUP(B35,'[1]Wages Sheet'!$B$8:$T$193,19,FALSE) -> 9000 | N35: =VLOOKUP(B35,'[1]Wages Sheet'!$B$8:$U$192,20,FALSE) -> 8400 | O35: =VLOOKUP(B35,'[1]Wages Sheet'!$B$8:$W$192,22,FALSE) -> 0 | P35: =VLOOKUP(B35,'[1]Wages Sheet'!$B$8:$Z$192,25,FALSE) -> 8420.4541 | Q35: =VLOOKUP(B35,'[1]Wages Sheet'!$B$8:$AD$192,28,FALSE) -> 16820.454 | R35: =VLOOKUP(B35,'[1]Wages Sheet'!$B$8:$AD$192,29,FALSE) -> 16820 | S35: =VLOOKUP(B35,'[1]Wages Sheet'!$B$8:$AF$192,31,FALSE) -> 0.45411674
A36: Apr 2026 | B36: Ghanshyam Ganjhu | C36: New | D36: T/H | F36: 30 | G36: 0 | H36: 30 | I36: =VLOOKUP(B36,'[1]Wages Sheet'!$B$8:$J$192,9,FALSE) -> 0 | J36: =SUM(VLOOKUP(B36,'[1]Wages Sheet'!$B$8:$K$192,10,FALSE)+(VLOOKUP(B36,'[1]Wages Sheet'!$B$8:$L$192,11,FALSE))) -> 0 | K36: =VLOOKUP(B36,'[1]Wages Sheet'!$B$8:$O$192,14,FALSE) -> 0 | L36: =VLOOKUP(B36,'[1]Wages Sheet'!$B$8:$Q$192,16,FALSE) -> 0 | M36: =VLOOKUP(B36,'[1]Wages Sheet'!$B$8:$T$193,19,FALSE) -> 9500 | N36: =VLOOKUP(B36,'[1]Wages Sheet'!$B$8:$U$192,20,FALSE) -> 0 | O36: =VLOOKUP(B36,'[1]Wages Sheet'!$B$8:$W$192,22,FALSE) -> 0 | P36: =VLOOKUP(B36,'[1]Wages Sheet'!$B$8:$Z$192,25,FALSE) -> 0 | Q36: =VLOOKUP(B36,'[1]Wages Sheet'!$B$8:$AD$192,28,FALSE) -> 0 | R36: =VLOOKUP(B36,'[1]Wages Sheet'!$B$8:$AD$192,29,FALSE) -> 0 | S36: =VLOOKUP(B36,'[1]Wages Sheet'!$B$8:$AF$192,31,FALSE) -> 0
A37: Apr 2026 | B37: Ghanshyam Mahto | C37: New | D37: N/G | E37: Karo | F37: 30 | G37: 28 | H37: 2 | I37: =VLOOKUP(B37,'[1]Wages Sheet'!$B$8:$J$192,9,FALSE) -> 0 | J37: =SUM(VLOOKUP(B37,'[1]Wages Sheet'!$B$8:$K$192,10,FALSE)+(VLOOKUP(B37,'[1]Wages Sheet'!$B$8:$L$192,11,FALSE))) -> 0 | K37: =VLOOKUP(B37,'[1]Wages Sheet'!$B$8:$O$192,14,FALSE) -> 0 | L37: =VLOOKUP(B37,'[1]Wages Sheet'!$B$8:$Q$192,16,FALSE) -> 0 | M37: =VLOOKUP(B37,'[1]Wages Sheet'!$B$8:$T$193,19,FALSE) -> 9000 | N37: =VLOOKUP(B37,'[1]Wages Sheet'!$B$8:$U$192,20,FALSE) -> 8400 | O37: =VLOOKUP(B37,'[1]Wages Sheet'!$B$8:$W$192,22,FALSE) -> 0 | P37: =VLOOKUP(B37,'[1]Wages Sheet'!$B$8:$Z$192,25,FALSE) -> 8128.868 | Q37: =VLOOKUP(B37,'[1]Wages Sheet'!$B$8:$AD$192,28,FALSE) -> 16528.868 | R37: =VLOOKUP(B37,'[1]Wages Sheet'!$B$8:$AD$192,29,FALSE) -> 16530 | S37: =VLOOKUP(B37,'[1]Wages Sheet'!$B$8:$AF$192,31,FALSE) -> -1.1320123
A38: Apr 2026 | B38: Ghanshyam Singh | C38: New | D38: D/OP | E38: Karo | F38: 30 | G38: 27 | H38: 3 | I38: =VLOOKUP(B38,'[1]Wages Sheet'!$B$8:$J$192,9,FALSE) -> -1 | J38: =SUM(VLOOKUP(B38,'[1]Wages Sheet'!$B$8:$K$192,10,FALSE)+(VLOOKUP(B38,'[1]Wages Sheet'!$B$8:$L$192,11,FALSE))) -> 4 | K38: =VLOOKUP(B38,'[1]Wages Sheet'!$B$8:$O$192,14,FALSE) -> 3 | L38: =VLOOKUP(B38,'[1]Wages Sheet'!$B$8:$Q$192,16,FALSE) -> 1 | M38: =VLOOKUP(B38,'[1]Wages Sheet'!$B$8:$T$193,19,FALSE) -> 17000 | N38: =VLOOKUP(B38,'[1]Wages Sheet'!$B$8:$U$192,20,FALSE) -> 17000 | O38: =VLOOKUP(B38,'[1]Wages Sheet'!$B$8:$W$192,22,FALSE) -> 0 | P38: =VLOOKUP(B38,'[1]Wages Sheet'!$B$8:$Z$192,25,FALSE) -> 12999.677 | Q38: =VLOOKUP(B38,'[1]Wages Sheet'!$B$8:$AD$192,28,FALSE) -> 29999.677 | R38: =VLOOKUP(B38,'[1]Wages Sheet'!$B$8:$AD$192,29,FALSE) -> 30000 | S38: =VLOOKUP(B38,'[1]Wages Sheet'!$B$8:$AF$192,31,FALSE) -> -0.32258065
